Workbook

Sheet Resumo
B3: Aquisição CNPJ | C3: 1 CNPJ | D3: 5 CNPJ
B4: ='Custos De Compra CNPJ - Societ.'!B4 -> Honorários + Impostos a calcular - ISS (5%), PIS/COFINS (9,25%) | C4: ='Custos De Compra CNPJ - Societ.'!C4 -> 9248.55 | D4: ='Custos De Compra CNPJ - Societ.'!E4 -> 46242.75
B5: ='Custos De Compra CNPJ - Societ.'!B22 -> Taxa de registro na JUCERJA | C5: ='Custos De Compra CNPJ - Societ.'!C22 -> 754 | D5: ='Custos De Compra CNPJ - Societ.'!E22 -> 3770
B6: ='Custos De Compra CNPJ - Societ.'!B25 -> Públicação da ata de AGE (alteração estatutária) e Estatuto Social (ato registrado pelo Eduardo Duarte) | C6: ='Custos De Compra CNPJ - Societ.'!C25 -> 28644 | D6: ='Custos De Compra CNPJ - Societ.'!E25 -> 143220
B7: Custos de ATD à fiscalização para matriz* (5 do RJ) | C7: ='Custos para Abertura de Filiais'!C2 -> 4000 | D7: =C7*5 -> 20000
B8: Certificado Digital | C8: ='Custos para Abertura de Filiais'!C3 -> 3000 | D8: =C8*5 -> 15000
B9: Total | C9: =SUM(C4:C8) -> 45646.55 | D9: =SUM(D4:D8) -> 228232.75
B11: Abertura de Filiais - 53 no total | C11: 1 CNPJ | D11: 5 CNPJ
B12: Procurações públicas da ClientCo (13 despachantes, sendo R$ 550 por procuração) | C12: =AVERAGE('Custos De Compra CNPJ - Societ.'!F35,'Custos De Compra CNPJ - Societ.'!F38,'Custos De Compra CNPJ - Societ.'!F41,'Custos De Compra CNPJ - Societ.'!F44,'Custos De Compra CNPJ - Societ.'!F47) -> 7150 | D12: ='Custos De Compra CNPJ - Societ.'!F35+'Custos De Compra CNPJ - Societ.'!F38+'Custos De Compra CNPJ - Societ.'!F41+'Custos De Compra CNPJ - Societ.'!F44+'Custos De Compra CNPJ - Societ.'!F47 -> 35750
B13: Registro das atas de ReDir da ClientCo (abertura de filiais/CD/CA - R$ 754,00 por ata) | C13: =AVERAGE('Custos De Compra CNPJ - Societ.'!F33,'Custos De Compra CNPJ - Societ.'!F36,'Custos De Compra CNPJ - Societ.'!F39,'Custos De Compra CNPJ - Societ.'!F42,'Custos De Compra CNPJ - Societ.'!F45) -> 7992.4 | D13: ='Custos De Compra CNPJ - Societ.'!F33+'Custos De Compra CNPJ - Societ.'!F36+'Custos De Compra CNPJ - Societ.'!F39+'Custos De Compra CNPJ - Societ.'!F42+'Custos De Compra CNPJ - Societ.'!F45 -> 39962
B14: Publicação de ReDir ClientCo (abertura de filiais/CD/CA - R$ 630,00 por ata publicada) | C14: =AVERAGE('Custos De Compra CNPJ - Societ.'!F34,'Custos De Compra CNPJ - Societ.'!F37,'Custos De Compra CNPJ - Societ.'!F40,'Custos De Compra CNPJ - Societ.'!F43,'Custos De Compra CNPJ - Societ.'!F46) -> 6678 | D14: ='Custos De Compra CNPJ - Societ.'!F34+'Custos De Compra CNPJ - Societ.'!F37+'Custos De Compra CNPJ - Societ.'!F40+'Custos De Compra CNPJ - Societ.'!F43+'Custos De Compra CNPJ - Societ.'!F46 -> 33390
B15: Custos de ATD à fiscalização para demais filiais* | C15: =AVERAGE('Custos para Abertura de Filiais'!G6:G38) -> 46400 | D15: ='Custos para Abertura de Filiais'!G42-D7 -> 212000
B16: Total | C16: =SUM(C12:C15) -> 68220.4 | D16: =SUM(D12:D15) -> 321102
B18: (*) Itens envolvidos | D18: =D9+D16 -> 549334.75
B19: Confecção de DBE junto a Receita Federal para Abertura de Filial
B20: Inscrição do CNPJ
B21: Inscrição Municipal
B22: Alvará de Funcionamento

Sheet Custos De Compra CNPJ - Societ.
C2: Custo Unitário | D2: Qtde Empresas | E2: Custo Total
B3: Honorário Liquido de compra empresa: | C3: 8000
B4: Honorários + Impostos a calcular - ISS (5%), PIS/COFINS (9,25%) | C4: 9248.55 | D4: 5 | E4: =C4*D4 -> 46242.75
B5: Não incluso no valor acima o IRPJ, CSSL | C5: << Valor ajustado após receber o valor do fornecedor em 27/03/24
B7: Despesa Inclusa:
B8: Inclusos ao valor dos honorários de regularização (*) da Companhia na Cidade do Rio de Janeiro, perante a Junta Comercial, Secretaria da Receita Federal, Prefeitura, inscrição junto ao cadastro da Secretaria de Estado de Fazenda (se necessário).
B9: (*) HONORÁRIOS DE REGULARIZAÇÃO: ALTERAÇÕES CONSTANTES NA 1ª AGE, DOCUMENTOS POSTERIORES SERÃO COBRADOS.
B11: Despesas não inclusas:
B12: Não inclusos as despesas e os impostos incidentes na nota fiscal de serviços.
B13: Outras Despesas não inclusas: taxa da Junta Comercial, cópias, autenticações, e outras despesas necessárias à regularização, essas despesas serão adiantadas pelo cliente e serão devidamente comprovadas com o envio dos comprovantes de pagamento, e ainda, os impostos incidentes sobre a Nota Fiscal, podendo a NF ser emitida pelas empresas do nosso grupo, são elas: EDCA Serviços Societários Ltda. – CNPJ/ME nº 30.321.763/0001-03 e Vec Editora e Serviços Ltda. – CNPJ/ME nº 30.279.129/0001-41.
B14: Não está incluso ao valor da aquisição, o registro da empresa junto à qualquer Conselho (CRC, CRA, CRM, CREA, Licenças, etc.), se necessário, os honorários ficarão à combinar.
B15: Caso o pagamento seja efetuado através de câmbio, as despesas com o fechamento do câmbio não estão inclusas no valor de aquisição da sociedade.
B18: REGULARIZAÇÃO DA MESMA NOS ÓRGÃOS COMPETENTES.
B19: Cenário 1 (Somente o registro na JUCERJA) | C19: Custo Unitário | D19: Qtde Empresas | E19: Custo Total
B20: Reembolso da taxa de registro na JUCERJA – R$ 754,00 | C20: 754 | D20: 5 | E20: =C20*D20 -> 3770
B21: Honorários – Isento | C21: 0
B22: Taxa de registro na JUCERJA | C22: =SUM(C20:C21) -> 754 | D22: 5 | E22: =C22*D22 -> 3770
C24: Custo Unitário | D24: Qtde Empresas | E24: Custo Total
B25: Públicação da ata de AGE (alteração estatutária) e Estatuto Social (ato registrado pelo Eduardo Duarte) | C25: 28644 | D25: 5 | E25: =C25*D25 -> 143220
B27: Total para Aquisição dos 5 CNPJs | E27: =E25+E22+E4 -> 193232.75
B28: Já aprovado pelo N1 em 22/03/24 | E28: 50000
B29: Aprovação Complementar em 27/03/24 | E29: =E27-E28 -> 143232.75 | F29: << parte 1
B32: Custos Societários para Abertura de Filiais por Client Co | C32: Client Co | D32: Custo Unitário | E32: Qtde filiais ex-matriz/ Despachantes | F32: Custo Total | G32: Custo por ClientCo
B33: Registro das atas de ReDir da ClientCo (abertura de 8 filiais e 7 CD/CA) | C33: 1 | D33: 754 | E33: =8+7-1 -> 14 | F33: =D33*E33 -> 10556 | G33: =SUM(F33:F35) -> 26526
B34: Publicação de ReDir ClientCo (abertura de 8 filiais e 7 CD/CA - R$ 630,00 por ata publicada) | C34: 1 | D34: 630 | E34: =8+7-1 -> 14 | F34: =D34*E34 -> 8820
B35: Procurações públicas da ClientCo (13 despachantes, sendo R$ 550 por procuração) | C35: 1 | D35: 550 | E35: 13 | F35: =D35*E35 -> 7150
B36: Registro das atas de ReDir (abertura de 10 filiais e 9 CD/CA) | C36: 2 | D36: 754 | E36: =10+9-1 -> 18 | F36: =D36*E36 -> 13572 | G36: =SUM(F36:F38) -> 32062
B37: Publicação de ReDir (abertura de 10 filiais e 9 CD/CA - R$ 630,00 por ata publicada) | C37: 2 | D37: 630 | E37: =10+9-1 -> 18 | F37: =D37*E37 -> 11340
B38: Procurações públicas (13 despachantes, sendo R$ 550 por procuração) | C38: 2 | D38: 550 | E38: 13 | F38: =D38*E38 -> 7150
B39: Registro das atas de ReDir (abertura de 4 filiais e 3 CD/CA) | C39: 3 | D39: 754 | E39: =4+3-1 -> 6 | F39: =D39*E39 -> 4524 | G39: =SUM(F39:F41) -> 15454
B40: Publicação de ReDir (abertura de 4 filiais e 3 CD/CA - R$ 630,00 por ata publicada) | C40: 3 | D40: 630 | E40: =4+3-1 -> 6 | F40: =D40*E40 -> 3780
B41: Procurações públicas (13 despachantes, sendo R$ 550 por procuração) | C41: 3 | D41: 550 | E41: 13 | F41: =D41*E41 -> 7150
B42: Registro das atas de ReDir (abertura de 6 filiais e 5 CD/CA) | C42: 4 | D42: 754 | E42: =6+5-1 -> 10 | F42: =D42*E42 -> 7540 | G42: =SUM(F42:F44) -> 20990
B43: Publicação de ReDir (abertura de 6 filiais e 5 CD/CA - R$ 630,00 por ata publicada) | C43: 4 | D43: 630 | E43: =6+5-1 -> 10 | F43: =D43*E43 -> 6300
B44: Procurações públicas (13 despachantes, sendo R$ 550 por procuração) | C44: 4 | D44: 550 | E44: 13 | F44: =D44*E44 -> 7150
B45: Registro das atas de ReDir (abertura de 3 filiais e 3 CD/CA) | C45: 5 | D45: 754 | E45: =3+3-1 -> 5 | F45: =D45*E45 -> 3770 | G45: =SUM(F45:F47) -> 14070
B46: Publicação de ReDir (abertura de 3 filiais e 3 CD/CA - R$ 630,00 por ata publicada) | C46: 5 | D46: 630 | E46: =3+3-1 -> 5 | F46: =D46*E46 -> 3150
B47: Procurações públicas (13 despachantes, sendo R$ 550 por procuração) | C47: 5 | D47: 550 | E47: 13 | F47: =D47*E47 -> 7150
B48: Total | F48: =SUM(F33:F47) -> 109102 | G48: =SUM(G33:G47) -> 109102
B50: Aprovação Complementar em 27/03/24 | F50: =F48 -> 109102 | G50: << parte 2
...

Sheet Custos para Abertura de Filiais
B2: Custo Médio de Mars para abertura de Filial na capital (*) | C2: 4000
B3: Custo dos Certificados Digitais por empresa | C3: 3000
C5: Qtde Filial por ClientCo | D5: Matriz Empresa | E5: Filiais p/ ClientCo - Clientes | F5: Filiais CD/CA de Logistica | G5: Custo para Regularização das Filiais | H5: Custo Filiais Clientes | I5: Custo Filiais Logística | J5: Custo dos Certificados Digitais
B6: CLIENTCO 1 | C6: 15 | D6: 1 | E6: 8 | F6: 7 | G6: =C6*$C$2 -> 60000 | H6: =E6*$C$2 -> 32000 | I6: =F6*$C$2 -> 28000 | J6: =$C$3 -> 3000
B7: AC | C7: 2 | E7: 1 | F7: 1
B8: AM | C8: 2 | E8: 1 | F8: 1
B9: AP | C9: 2 | E9: 1 | F9: 1
B10: PA | C10: 2 | E10: 1 | F10: 1
B11: RJ | C11: 1 | D11: 1 | E11: 1 | F11: 0
B12: RO | C12: 2 | E12: 1 | F12: 1
B13: RR | C13: 2 | E13: 1 | F13: 1
B14: TO | C14: 2 | E14: 1 | F14: 1
B15: CLIENTCO 2 | C15: 19 | D15: 1 | E15: 10 | F15: 9 | G15: =C15*$C$2 -> 76000 | H15: =E15*$C$2 -> 40000 | I15: =F15*$C$2 -> 36000 | J15: =$C$3 -> 3000
B16: AL | C16: 2 | E16: 1 | F16: 1
B17: BA | C17: 2 | E17: 1 | F17: 1
B18: CE | C18: 2 | E18: 1 | F18: 1
B19: MA | C19: 2 | E19: 1 | F19: 1
B20: PB | C20: 2 | E20: 1 | F20: 1
B21: PE | C21: 2 | E21: 1 | F21: 1
B22: PI | C22: 2 | E22: 1 | F22: 1
B23: RJ | C23: 1 | D23: 1 | E23: 1 | F23: 0
B24: RN | C24: 2 | E24: 1 | F24: 1
B25: SE | C25: 2 | E25: 1 | F25: 1
B26: CLIENTCO 3 | C26: 7 | D26: 1 | E26: 4 | F26: 3 | G26: =C26*$C$2 -> 28000 | H26: =E26*$C$2 -> 16000 | I26: =F26*$C$2 -> 12000 | J26: =$C$3 -> 3000
B27: PR | C27: 2 | E27: 1 | F27: 1
B28: RJ | C28: 1 | D28: 1 | E28: 1 | F28: 0
B29: RS | C29: 2 | E29: 1 | F29: 1
B30: SC | C30: 2 | E30: 1 | F30: 1
B31: CLIENTCO 4 | C31: 11 | D31: 1 | E31: 6 | F31: 5 | G31: =C31*$C$2 -> 44000 | H31: =E31*$C$2 -> 24000 | I31: =F31*$C$2 -> 20000 | J31: =$C$3 -> 3000
B32: DF | C32: 2 | E32: 1 | F32: 1
B33: GO | C33: 2 | E33: 1 | F33: 1
B34: MG | C34: 2 | E34: 1 | F34: 1
B35: MS | C35: 2 | E35: 1 | F35: 1
B36: MT | C36: 2 | E36: 1 | F36: 1
B37: RJ | C37: 1 | D37: 1 | E37: 1 | F37: 0
B38: CLIENTCO 5 | C38: 6 | D38: 1 | E38: 3 | F38: 3 | G38: =C38*$C$2 -> 24000 | H38: =E38*$C$2 -> 12000 | I38: =F38*$C$2 -> 12000 | J38: =$C$3 -> 3000
B39: ES | C39: 2 | E39: 1 | F39: 1
B40: RJ | C40: 2 | D40: 1 | E40: 1 | F40: 1
B41: SP | C41: 2 | E41: 1 | F41: 1
B42: Total Geral | C42: 58 | D42: 5 | E42: 31 | F42: 27 | G42: =C42*$C$2 -> 232000 | H42: =E42*$C$2 -> 124000 | I42: =F42*$C$2 -> 108000 | J42: =SUM(J6,J15,J26,J31,J38) -> 15000 | K42: =G42+J42 -> 247000
...

Sheet Capitais Societário
A1: CHAVE | B1: Empresa | C1: Nome da Empresa | D1: BLOCO | E1: UF | F1: PREVE DROP DE CLIENTES? | G1: CLASSIFICAÇÃO | H1: Qtde
A2: =C2&E2 -> CLIENTCO 1AC | B2: CCOX | C2: CLIENTCO 1 | D2: 1 | E2: AC | F2: SIM | G2: FILIAL | H2: 1
A3: =C3&E3 -> CLIENTCO 1RO | B3: CCOX | C3: CLIENTCO 1 | D3: 1 | E3: RO | F3: SIM | G3: FILIAL | H3: 1
A4: =C4&E4 -> CLIENTCO 1TO | B4: CCOX | C4: CLIENTCO 1 | D4: 1 | E4: TO | F4: SIM | G4: FILIAL | H4: 1
A5: =C5&E5 -> CLIENTCO 1AP | B5: CCOX | C5: CLIENTCO 1 | D5: 1 | E5: AP | F5: SIM | G5: FILIAL | H5: 1
A6: =C6&E6 -> CLIENTCO 1AM | B6: CCOX | C6: CLIENTCO 1 | D6: 1 | E6: AM | F6: SIM | G6: FILIAL | H6: 1
A7: =C7&E7 -> CLIENTCO 1RR | B7: CCOX | C7: CLIENTCO 1 | D7: 1 | E7: RR | F7: SIM | G7: FILIAL | H7: 1
A8: =C8&E8 -> CLIENTCO 1PA | B8: CCOX | C8: CLIENTCO 1 | D8: 1 | E8: PA | F8: SIM | G8: FILIAL | H8: 1
A9: =C9&E9 -> CLIENTCO 1RJ | B9: CCOX | C9: CLIENTCO 1 | D9: 1 | E9: RJ | F9: NÃO | G9: MATRIZ | H9: 1
A10: =C10&E10 -> CLIENTCO 2MA | B10: CCOY | C10: CLIENTCO 2 | D10: 2 | E10: MA | F10: SIM | G10: FILIAL | H10: 1
A11: =C11&E11 -> CLIENTCO 2PI | B11: CCOY | C11: CLIENTCO 2 | D11: 2 | E11: PI | F11: SIM | G11: FILIAL | H11: 1
A12: =C12&E12 -> CLIENTCO 2CE | B12: CCOY | C12: CLIENTCO 2 | D12: 2 | E12: CE | F12: SIM | G12: FILIAL | H12: 1
A13: =C13&E13 -> CLIENTCO 2PB | B13: CCOY | C13: CLIENTCO 2 | D13: 2 | E13: PB | F13: SIM | G13: FILIAL | H13: 1
... A32: =C32&E32 -> CLIENTCO 5SP | B32: CCOO | C32: CLIENTCO 5 | D32: 5 | E32: SP | F32: SIM | G32: FILIAL | H32: 1
H33: =SUM(H2:H32) -> 31

Sheet Municipios Logística
I1: Custos de Despachante deverão ser cobrados por fora
B2: Relação dos Municipios
B3: Justificativa: | C3: A nova Oi tem por objetivo a recuperação do crédito de ICMS nas aquisições ONT e para realizar as operações logísticas, necessita buscar novo OL na UF | I3: Custos de Locomoção
I4: Cobrança pelo serviços (Hora)
B5: Operação | C5: Estado | D5: Nome do Fornecedor | E5: Endereço de Entrega | F5: Município | G5: UPI
A6: 1 | B6: CA-CD | C6: PA | D6: FedEx | E6: TERMINAL DE CARGAS DE BELÉM - ROD. BR 316 KM 07 MOD A E D (PÁTIO EXTERNO) - LEVILÂNDIA, CEP: 67030-000 - ANANINDEUA/PA | F6: ANANINDEUA | G6: =VLOOKUP(C6,[1]Logistica!$D$2:$G$28,4,0) -> CLIENTCO 1
A7: 2 | B7: CA-CD | C7: AM | D7: FedEx | E7: AV. PRESIDENTE KENNEDY, 920 - EDUCANDOS, CEP 69074-000, MANAUS/AM | F7: MANAUS | G7: =VLOOKUP(C7,[1]Logistica!$D$2:$G$28,4,0) -> CLIENTCO 1
A8: 3 | B8: CA | C8: AP | D8: Serede | E8: AV STEPHAN HOUAT SN, LOTE 01, JARDIM MARCO ZERO, CEP 68.903-193, MACAPÁ/AP | F8: MACAPÁ | G8: =VLOOKUP(C8,[1]Logistica!$D$2:$G$28,4,0) -> CLIENTCO 1
A9: 4 | B9: CA | C9: RR | D9: Serede | E9: RUA LEONCIO BARBOSA N° 1451 /CEP 69313-508, TANCREDO NEVES, BOA VISTA/RR | F9: BOA VISTA | G9: =VLOOKUP(C9,[1]Logistica!$D$2:$G$28,4,0) -> CLIENTCO 1
A10: 5 | B10: CA | C10: AC | D10: Telemont | E10: AV. BRASIL, Nº 638, CONJUNTO XAVIER MAIA, CEP 69903-018, RIO BRANCO/AC | F10: RIO BRANCO | G10: =VLOOKUP(C10,[1]Logistica!$D$2:$G$28,4,0) -> CLIENTCO 1
A11: 6 | B11: CA | C11: RO | D11: Telemont | E11: AV. RAIMUNDO CANTUÁRIA, 2881, BAIRRO ROQUE, CEP. 76.804-434 PORTO VELHO/RO | F11: PORTO VELHO | G11: =VLOOKUP(C11,[1]Logistica!$D$2:$G$28,4,0) -> CLIENTCO 1
A12: 7 | B12: CA | C12: TO | D12: Telemont | E12: ROD TO-050, KM 07, CHACARA RAQUEL Nº SN GALPÃO 02 B CENTRO TAQUARALTO, CEP. 77023-476, PALMAS/TO | F12: PALMAS | G12: =VLOOKUP(C12,[1]Logistica!$D$2:$G$28,4,0) -> CLIENTCO 1
A13: 8 | B13: CA-CD | C13: PE | D13: FedEx | E13: BR 101 SUL KM 96,4 Nº 5225 - GALPÃO 03 MÓDULO 04 - DISTRITO INDUSTRIAL DIPER, CEP: 54503-900, CABO DE SANTO AGOSTINHO/PE | F13: CABO DE SANTO AGOSTINHO | G13: =VLOOKUP(C13,[1]Logistica!$D$2:$G$28,4,0) -> CLIENTCO 2
A14: 9 | B14: CA-CD | C14: BA | D14: FedEx | E14: CELOG – VIA DE ACESSO II, QUADRA 2 LOTE 53 VIA SUL, CEP 437000-000, SIMÕES FILHO/BA, | F14: SIMÕES FILHO | G14: =VLOOKUP(C14,[1]Logistica!$D$2:$G$28,4,0) -> CLIENTCO 2
A15: 10 | B15: CA | C15: AL | D15: Serede | E15: AV. PRES GETULIO VARGAS 66, SERRARIA, CEP 57045-140, MACEIO/AL | F15: MACEIO | G15: =VLOOKUP(C15,[1]Logistica!$D$2:$G$28,4,0) -> CLIENTCO 2
A16: 11 | B16: CA | C16: CE | D16: Serede | E16: RUA WENEFRIDO MELO, 290, MONDUBIM, CEP: 60762-410, FORTALEZA/CE | F16: FORTALEZA | G16: =VLOOKUP(C16,[1]Logistica!$D$2:$G$28,4,0) -> CLIENTCO 2
A17: 12 | B17: CA | C17: MA | D17: Serede | E17: R. FREI HERMENEGILDO - AURORA, CEP 65060-190, SÃO LUÍS/MA | F17: SÃO LUIS | G17: =VLOOKUP(C17,[1]Logistica!$D$2:$G$28,4,0) -> CLIENTCO 2
... A32: 27 | B32: CA | C32: SP | D32: Telemont | E32: RUA JOÃO GALVÃO ANDERSON, 243-CONDOMINIO TICLOG, TERMINAL INDUSTRIAL DE CARGAS E LOGÍSTICA, CEP: 13069-107, CAMPINAS/SP | F32: CAMPINAS | G32: =VLOOKUP(C32,[1]Logistica!$D$2:$G$28,4,0) -> CLIENTCO 5
