Workbook

Sheet Resumo
B5: Área Responsável: Suprimentos Serede - Gerente: Marcelo de Oliveira Santos - 21 - 98754-9966
B6: Fonte: SAP Serede (extraído em 14/02/2025)
B11: Base de Fornecedores distribuído da forma abaixo:
B13: Possui Contrato? | C13: Qtde Fornecedor
B14: Sim | C14: 93
B15: Não | C15: 4342
B16: Total Geral | C16: 4435
B18: Fornecedores com faturamento em 2024/2025 (não considera 2023):
B20: Faturamento em 2024/25 | C20: Qtde Fornecedor
B21: Sim | C21: 321
B22: Não | C22: 4114
B23: Total Geral | C23: 4435
B25: Grupo de Contas:
B27: Rótulos de Linha | C27: Contagem de Grupo Contas
B28: Prefeituras - PJ | C28: 2599
B29: Fornec. de Serviç. Diversos PJ | C29: 1216
B30: Órgãos Públicos - PJ | C30: 306
B31: Fornecedor de materiais - PJ | C31: 79
B32: Hotéis e Pousadas - PJ | C32: 69
B33: Pagamentos judiciais - PJ | C33: 62
B34: Consultorias - PJ | C34: 21
B35: Fretes - PJ | C35: 12
B36: Locação de Equipamentos - PJ | C36: 12
B37: Serviços de Operaç./Engenh. PJ | C37: 10
B38: TRIBUTOS | C38: 9
B39: Pessoa Física - PF | C39: 8
... B49: Total Geral | C49: 4435

Sheet Tabela Base SAP
A1: Fornecedor | B1: Nome | C1: Fornecedor | D1: Dt. Abertura | E1: Criado por | F1: Rua | G1: Local | H1: Bairro | I1: Região | J1: Cód.postal | K1: País | L1: Telefone 1 | M1: Nº telefax | N1: CNPJ | O1: CPF | P1: Insc Est | Q1: Insc Muni | R1: Endereço de e-mail | S1: Empresa | T1: Sigla Grupo Conta | U1: Grupo Contas | V1: ChvBanco | W1: ContaBanc. | X1: ChvCtrlBco | Y1: Nº Contrato | Z1: Dt. Últ. PC | AA1: Contrato: Sim/Não | AB1: PC e/ou Faturamento em 2024-25? | AC1: zEmpresa
A2: 200669 | B2: PREFEITURA MUNICIPAL DE CURITIBA | C2: 200669 | D2: 41267 | E2: CARGA | F2: AVENIDA CANDIDO DE ABREU 817 817 | G2: CURITIBA | H2: CENTRO CIVICO | I2: PR | J2: 80530-908 | K2: BR | L2: 4133508484 | S2: TSR | T2: FPRE | U2: =VLOOKUP(T2,Apoio!$D$10:$E$55,2,0) -> Prefeituras - PJ | AA2: =IF(Y2="","Não","Sim") -> Não | AB2: =IF(Z2="","Não","Sim") -> Não | AC2: =IF(S2="TSR","Serede","Rede Conecta") -> Serede
A3: 2609626 | B3: MARCOS ANDRE COLETA | C3: 2609626 | D3: 41270 | E3: CARGA | F3: AUGUSTO LIRA 153 | G3: RECIFE | H3: VASCO DA GAMA | I3: PE | J3: 52081-120 | K3: BR | P3: ISENTA | S3: TSR | T3: FPFZ | U3: =VLOOKUP(T3,Apoio!$D$10:$E$55,2,0) -> Pessoa Física - PF | V3: 191833 | W3: 24891 | X3: 36 | AA3: =IF(Y3="","Não","Sim") -> Não | AB3: =IF(Z3="","Não","Sim") -> Não | AC3: =IF(S3="TSR","Serede","Rede Conecta") -> Serede
A4: 204907 | B4: PREFEITURA MUNICIPAL DE SAO CRISTOV | C4: 204907 | D4: 41273 | E4: CARGA | F4: PRACA DR GETULIO VARGAS 298 | G4: SAO CRISTOVAO | H4: CENTRO | I4: SE | J4: 49100-000 | K4: BR | S4: TSR | T4: FPRE | U4: =VLOOKUP(T4,Apoio!$D$10:$E$55,2,0) -> Prefeituras - PJ | AA4: =IF(Y4="","Não","Sim") -> Não | AB4: =IF(Z4="","Não","Sim") -> Não | AC4: =IF(S4="TSR","Serede","Rede Conecta") -> Serede
A5: 2000002 | B5: COMBUSTIVEL | C5: 2000002 | D5: 41273 | E5: R88866521353 | F5: RUA MARCOS MACEDO 1333 | G5: FORTAELZA | I5: CE | J5: 60150-190 | K5: BR | S5: TSR | T5: FTRI | U5: =VLOOKUP(T5,Apoio!$D$10:$E$55,2,0) -> TRIBUTOS | AA5: =IF(Y5="","Não","Sim") -> Não | AB5: =IF(Z5="","Não","Sim") -> Não | AC5: =IF(S5="TSR","Serede","Rede Conecta") -> Serede
A6: 2000005 | B6: LOCACAO DE VEICULOS | C6: 2000005 | D6: 41273 | E6: R88866521353 | F6: RUA MARCOS MACEDO 1333 | G6: FORTALEZA | I6: CE | J6: 60150-190 | K6: BR | S6: TSR | T6: FTRI | U6: =VLOOKUP(T6,Apoio!$D$10:$E$55,2,0) -> TRIBUTOS | AA6: =IF(Y6="","Não","Sim") -> Não | AB6: =IF(Z6="","Não","Sim") -> Não | AC6: =IF(S6="TSR","Serede","Rede Conecta") -> Serede
A7: 2000006 | B7: SECRETARIA DA RECEITA FEDERAL | C7: 2000006 | D7: 41273 | E7: R88866521353 | F7: RUA MARCOS MACEDO 1333 | G7: FORTALEZA | I7: CE | J7: 60150-190 | K7: BR | S7: TSR | T7: FTRI | U7: =VLOOKUP(T7,Apoio!$D$10:$E$55,2,0) -> TRIBUTOS | V7: 0 | W7: 99999999 | X7: 0 | AA7: =IF(Y7="","Não","Sim") -> Não | AB7: =IF(Z7="","Não","Sim") -> Não | AC7: =IF(S7="TSR","Serede","Rede Conecta") -> Serede
A8: 2000007 | B8: INSTITUTO NAC DA SEGURIDADE SOCIAL | C8: 2000007 | D8: 41273 | E8: R88866521353 | F8: RUA MARCOS MACEDO 1333 | G8: FORTALEZA | I8: CE | J8: 60150-190 | K8: BR | S8: TSR | T8: FTRI | U8: =VLOOKUP(T8,Apoio!$D$10:$E$55,2,0) -> TRIBUTOS | V8: 0 | W8: 99999999 | X8: 0 | AA8: =IF(Y8="","Não","Sim") -> Não | AB8: =IF(Z8="","Não","Sim") -> Não | AC8: =IF(S8="TSR","Serede","Rede Conecta") -> Serede
A9: 2000008 | B9: SECRETARIA ESTADUAL DA PARAIBA | C9: 2000008 | D9: 41273 | E9: R88866521353 | F9: RUA JOAO DA MATA SN | G9: AGUA BRANCA | I9: PB | J9: 58015-020 | K9: BR | S9: TSR | T9: FTRI | U9: =VLOOKUP(T9,Apoio!$D$10:$E$55,2,0) -> TRIBUTOS | AA9: =IF(Y9="","Não","Sim") -> Não | AB9: =IF(Z9="","Não","Sim") -> Não | AC9: =IF(S9="TSR","Serede","Rede Conecta") -> Serede
A10: 2000009 | B10: SECRETARIA ESTADUAL DO PIAUI | C10: 2000009 | D10: 41273 | E10: R88866521353 | F10: AVENIDA PEDRO FREITAS SN | G10: TERESINA | I10: PI | J10: 64018-900 | K10: BR | S10: TSR | T10: FTRI | U10: =VLOOKUP(T10,Apoio!$D$10:$E$55,2,0) -> TRIBUTOS | AA10: =IF(Y10="","Não","Sim") -> Não | AB10: =IF(Z10="","Não","Sim") -> Não | AC10: =IF(S10="TSR","Serede","Rede Conecta") -> Serede
A11: 2000010 | B11: SECRETARIA ESTADUAL DO MARANHAO | C11: 2000010 | D11: 41273 | E11: R88866521353 | F11: RUA SANTA ISABEL 40 | G11: SAO LUIS | I11: MA | J11: 65076-090 | K11: BR | S11: TSR | T11: FTRI | U11: =VLOOKUP(T11,Apoio!$D$10:$E$55,2,0) -> TRIBUTOS | AA11: =IF(Y11="","Não","Sim") -> Não | AB11: =IF(Z11="","Não","Sim") -> Não | AC11: =IF(S11="TSR","Serede","Rede Conecta") -> Serede
A12: 2000011 | B12: PREFEITURA MUNICIPAL SAO CRISTOVAO | C12: 2000011 | D12: 41273 | E12: R88866521353 | F12: PRACA DR GETULIO VARGAS 298 | G12: SAO CRISTOVAO | I12: SE | J12: 49100-000 | K12: BR | S12: TSR | T12: FTRI | U12: =VLOOKUP(T12,Apoio!$D$10:$E$55,2,0) -> TRIBUTOS | AA12: =IF(Y12="","Não","Sim") -> Não | AB12: =IF(Z12="","Não","Sim") -> Não | AC12: =IF(S12="TSR","Serede","Rede Conecta") -> Serede
A13: 304032 | B13: PROCURADORIA GERAL | C13: 304032 | D13: 41333 | E13: R01144195314 | F13: RUA MARCOS MACEDO 1333 | G13: FORTALEZA | H13: PAPICU | I13: CE | J13: 60150-190 | K13: BR | S13: TSR | T13: FOPU | U13: =VLOOKUP(T13,Apoio!$D$10:$E$55,2,0) -> Órgãos Públicos - PJ | AA13: =IF(Y13="","Não","Sim") -> Não | AB13: =IF(Z13="","Não","Sim") -> Não | AC13: =IF(S13="TSR","Serede","Rede Conecta") -> Serede
A14: 204931 | B14: GLORIA DE GOITA PREFEITURA | C14: 204931 | D14: 41368 | E14: R01144195314 | F14: PRAÇA CRISTO REDENTOR 08 | G14: GLORIA DO GOITA | H14: CENTRO | I14: PE | J14: 55620-000 | K14: BR | S14: TSR | T14: FPRE | U14: =VLOOKUP(T14,Apoio!$D$10:$E$55,2,0) -> Prefeituras - PJ | AA14: =IF(Y14="","Não","Sim") -> Não | AB14: =IF(Z14="","Não","Sim") -> Não | AC14: =IF(S14="TSR","Serede","Rede Conecta") -> Serede
A15: 304038 | B15: DEPARTAMENTO DE INFRAESTRUTURA | C15: 304038 | D15: 41389 | E15: R01144195314 | F15: 4ª AVENIDA 445 | G15: SALVADOR | H15: CENTRO ADMINISTRATIVO DA BAHIA | I15: BA | J15: 41745-002 | K15: BR | S15: TSR | T15: FOPU | U15: =VLOOKUP(T15,Apoio!$D$10:$E$55,2,0) -> Órgãos Públicos - PJ | AA15: =IF(Y15="","Não","Sim") -> Não | AB15: =IF(Z15="","Não","Sim") -> Não | AC15: =IF(S15="TSR","Serede","Rede Conecta") -> Serede
A16: 304042 | B16: CORPO DE BOMBEIROS MILITAR FUNESBOM | C16: 304042 | D16: 41411 | E16: R01144195314 | F16: RUA SAO LUIZ GONZAGA 2244 | G16: RIO DE JANEIRO | H16: BENFICA | I16: RJ | J16: 20910-062 | K16: BR | S16: TSR | T16: FOPU | U16: =VLOOKUP(T16,Apoio!$D$10:$E$55,2,0) -> Órgãos Públicos - PJ | AA16: =IF(Y16="","Não","Sim") -> Não | AB16: =IF(Z16="","Não","Sim") -> Não | AC16: =IF(S16="TSR","Serede","Rede Conecta") -> Serede
A17: 2700016 | B17: WILLIAMS INTERNACIONAL CO. | C17: 2700016 | D17: 41429 | E17: R01144195314 | F17: 200 P.O BOX | G17: DETROID | H17: WALLED LAKE | I17: XE | J17: 48390-0200 | K17: US | S17: TSR | T17: FEST | U17: =VLOOKUP(T17,Apoio!$D$10:$E$55,2,0) -> Fornecedor Estrangeiro | AA17: =IF(Y17="","Não","Sim") -> Não | AB17: =IF(Z17="","Não","Sim") -> Não | AC17: =IF(S17="TSR","Serede","Rede Conecta") -> Serede
A18: 304053 | B18: JUSTIÇA FEDERAL DO CEARÁ | C18: 304053 | D18: 41528 | E18: R01144195314 | F18: RUA DA ASSUNÇÃO SN | G18: FORTALEZA | H18: CENTRO | I18: CE | J18: 60025-130 | K18: BR | S18: TSR | T18: FOPU | U18: =VLOOKUP(T18,Apoio!$D$10:$E$55,2,0) -> Órgãos Públicos - PJ | AA18: =IF(Y18="","Não","Sim") -> Não | AB18: =IF(Z18="","Não","Sim") -> Não | AC18: =IF(S18="TSR","Serede","Rede Conecta") -> Serede
A19: 2700031 | B19: LINKEDIN IRELAND LIMITED | C19: 2700031 | D19: 41625 | E19: R01144195314 | F19: 9999 HOUSE GARDEN, WILTON PLACE | G19: EXTRANGEIRO | I19: XE | J19: 0 | K19: US | S19: TSR | T19: FEST | U19: =VLOOKUP(T19,Apoio!$D$10:$E$55,2,0) -> Fornecedor Estrangeiro | AA19: =IF(Y19="","Não","Sim") -> Não | AB19: =IF(Z19="","Não","Sim") -> Não | AC19: =IF(S19="TSR","Serede","Rede Conecta") -> Serede
A20: 304057 | B20: INPI - INSTITUTO NACIONAL DA PROPRI | C20: 304057 | D20: 41831 | E20: R01144195314 | F20: RUA MARIO MARTINS COELHO 36 | G20: FORTALEZA | H20: ALDEOTA | I20: CE | J20: 60170-280 | K20: BR | S20: TSR | T20: FOPU | U20: =VLOOKUP(T20,Apoio!$D$10:$E$55,2,0) -> Órgãos Públicos - PJ | AA20: =IF(Y20="","Não","Sim") -> Não | AB20: =IF(Z20="","Não","Sim") -> Não | AC20: =IF(S20="TSR","Serede","Rede Conecta") -> Serede
A21: 304077 | B21: TRIBUNAL DE JUSTIÇA DO ESTADO DO CE | C21: 304077 | D21: 42031 | E21: R01144195314 | F21: AVENIDA GENERAL ALBUQUERQUE LIMA SN | G21: FORTALEZA | H21: CAMBEBA | I21: CE | J21: 60822-325 | K21: BR | S21: TSR | T21: FOPU | U21: =VLOOKUP(T21,Apoio!$D$10:$E$55,2,0) -> Órgãos Públicos - PJ | AA21: =IF(Y21="","Não","Sim") -> Não | AB21: =IF(Z21="","Não","Sim") -> Não | AC21: =IF(S21="TSR","Serede","Rede Conecta") -> Serede
A22: 304092 | B22: CONSELHO REGIONAL DE ENG E AGRON | C22: 304092 | D22: 42384 | E22: R60531985369 | F22: Av. Brigadeiro Faria Lima 1059 | G22: SAO PAULO | H22: PINHEIROS | I22: SP | J22: 014529-20 | K22: BR | R22: atendimento@creasp.org.br | S22: TSR | T22: FOPU | U22: =VLOOKUP(T22,Apoio!$D$10:$E$55,2,0) -> Órgãos Públicos - PJ | V22: 193336 | W22: 70824 | X22: 70 | AA22: =IF(Y22="","Não","Sim") -> Não | AB22: =IF(Z22="","Não","Sim") -> Não | AC22: =IF(S22="TSR","Serede","Rede Conecta") -> Serede
A23: 304099 | B23: DEPÓSITO JUDICIAL-TRESPASSE RS | C23: 304099 | D23: 42465 | E23: R04835156390 | F23: RUA MARCOS MACEDO 1333 | G23: FORTALEZA | H23: ALDEOTA | I23: CE | J23: 60150-190 | K23: BR | S23: TSR | T23: FOPU | U23: =VLOOKUP(T23,Apoio!$D$10:$E$55,2,0) -> Órgãos Públicos - PJ | AA23: =IF(Y23="","Não","Sim") -> Não | AB23: =IF(Z23="","Não","Sim") -> Não | AC23: =IF(S23="TSR","Serede","Rede Conecta") -> Serede
A24: 304114 | B24: DEPARTAMENTO ESTADUAL DE TRANSITO | C24: 304114 | D24: 42710 | E24: R04835156390 | F24: AV. MARQUES DE SANTA CRUZ 218 | G24: MANAUS | H24: CENTRO | I24: AM | J24: 69005-050 | K24: BR | S24: TSR | T24: FOPU | U24: =VLOOKUP(T24,Apoio!$D$10:$E$55,2,0) -> Órgãos Públicos - PJ | AA24: =IF(Y24="","Não","Sim") -> Não | AB24: =IF(Z24="","Não","Sim") -> Não | AC24: =IF(S24="TSR","Serede","Rede Conecta") -> Serede
A25: 304115 | B25: DEPARTAMENTO ESTADUAL DE TRANSITO | C25: 304115 | D25: 42710 | E25: R04835156390 | F25: AV. BRG. EDUARDO GOMES 4214 | G25: BOA VISTA | H25: AEROPORTO | I25: RR | J25: 69305-455 | K25: BR | S25: TSR | T25: FOPU | U25: =VLOOKUP(T25,Apoio!$D$10:$E$55,2,0) -> Órgãos Públicos - PJ | AA25: =IF(Y25="","Não","Sim") -> Não | AB25: =IF(Z25="","Não","Sim") -> Não | AC25: =IF(S25="TSR","Serede","Rede Conecta") -> Serede
A26: 304116 | B26: DEPARTAMENTO ESTADUAL DE TRANSITO | C26: 304116 | D26: 42711 | E26: R04835156390 | F26: AV. ANTONIO BORGES 212 | G26: GRAJAÚ | H26: TRIZIDELA | I26: MA | J26: 65940-000 | K26: BR | S26: TSR | T26: FOPU | U26: =VLOOKUP(T26,Apoio!$D$10:$E$55,2,0) -> Órgãos Públicos - PJ | AA26: =IF(Y26="","Não","Sim") -> Não | AB26: =IF(Z26="","Não","Sim") -> Não | AC26: =IF(S26="TSR","Serede","Rede Conecta") -> Serede
A27: 304117 | B27: DEPARTAMENTO ESTADUAL DE TRANSITO | C27: 304117 | D27: 42711 | E27: R04835156390 | F27: AV. INDUSTRIAL GIL MARTINS 2000 | G27: TERESINA | H27: REDENÇÃO | I27: PI | J27: 64019-630 | K27: BR | S27: TSR | T27: FOPU | U27: =VLOOKUP(T27,Apoio!$D$10:$E$55,2,0) -> Órgãos Públicos - PJ | AA27: =IF(Y27="","Não","Sim") -> Não | AB27: =IF(Z27="","Não","Sim") -> Não | AC27: =IF(S27="TSR","Serede","Rede Conecta") -> Serede
A28: 304118 | B28: DEPARTAMENTO ESTADUAL DE TRANSITO | C28: 304118 | D28: 42711 | E28: R04835156390 | F28: RUA RIO BRANCO 493 | G28: SANTA CRUZ | H28: CENTRO | I28: RN | J28: 59200-000 | K28: BR | S28: TSR | T28: FOPU | U28: =VLOOKUP(T28,Apoio!$D$10:$E$55,2,0) -> Órgãos Públicos - PJ | AA28: =IF(Y28="","Não","Sim") -> Não | AB28: =IF(Z28="","Não","Sim") -> Não | AC28: =IF(S28="TSR","Serede","Rede Conecta") -> Serede
A29: 304119 | B29: DEPARTAMENTO ESTADUAL DE TRANSITO | C29: 304119 | D29: 42711 | E29: R04835156390 | F29: RUA EMILIA BATISTA CELANE | G29: JOÃO PESSOA | H29: MANGABEIRA VII | I29: PB | J29: 58058-280 | K29: BR | S29: TSR | T29: FOPU | U29: =VLOOKUP(T29,Apoio!$D$10:$E$55,2,0) -> Órgãos Públicos - PJ | AA29: =IF(Y29="","Não","Sim") -> Não | AB29: =IF(Z29="","Não","Sim") -> Não | AC29: =IF(S29="TSR","Serede","Rede Conecta") -> Serede
A30: 304120 | B30: DEPARTAMENTO ESTADUAL DE TRANSITO | C30: 304120 | D30: 42711 | E30: R04835156390 | F30: AV. PRESIDENTE KENNEDY 1001 | G30: OLINDA | H30: PEIXINHOS | I30: PE | J30: 53230-630 | K30: BR | S30: TSR | T30: FOPU | U30: =VLOOKUP(T30,Apoio!$D$10:$E$55,2,0) -> Órgãos Públicos - PJ | AA30: =IF(Y30="","Não","Sim") -> Não | AB30: =IF(Z30="","Não","Sim") -> Não | AC30: =IF(S30="TSR","Serede","Rede Conecta") -> Serede
A31: 304121 | B31: DEPARTAMENTO ESTADUAL DE TRANSITO | C31: 304121 | D31: 42711 | E31: R04835156390 | F31: AV. MENINO MARCELO 99 | G31: MACEIÓ | H31: CIDADE UNIVERSITÁRIA | I31: AL | J31: 57073-470 | K31: BR | S31: TSR | T31: FOPU | U31: =VLOOKUP(T31,Apoio!$D$10:$E$55,2,0) -> Órgãos Públicos - PJ | AA31: =IF(Y31="","Não","Sim") -> Não | AB31: =IF(Z31="","Não","Sim") -> Não | AC31: =IF(S31="TSR","Serede","Rede Conecta") -> Serede
A32: 304122 | B32: DEPARTAMENTO ESTADUAL DE TRANSITO | C32: 304122 | D32: 42711 | E32: R04835156390 | F32: AV. TRANCREDO NEVES | G32: ARACAJU | H32: PONTO NOVO | I32: SE | J32: 49040-490 | K32: BR | S32: TSR | T32: FOPU | U32: =VLOOKUP(T32,Apoio!$D$10:$E$55,2,0) -> Órgãos Públicos - PJ | AA32: =IF(Y32="","Não","Sim") -> Não | AB32: =IF(Z32="","Não","Sim") -> Não | AC32: =IF(S32="TSR","Serede","Rede Conecta") -> Serede
A33: 304123 | B33: DEPARTAMENTO ESTADUAL DE TRANSITO | C33: 304123 | D33: 42711 | E33: R04835156390 | F33: RUA ANTONIO BARBOSA NASCIMENTO | G33: CANARANA | I33: BA | J33: 44890-000 | K33: BR | S33: TSR | T33: FOPU | U33: =VLOOKUP(T33,Apoio!$D$10:$E$55,2,0) -> Órgãos Públicos - PJ | AA33: =IF(Y33="","Não","Sim") -> Não | AB33: =IF(Z33="","Não","Sim") -> Não | AC33: =IF(S33="TSR","Serede","Rede Conecta") -> Serede
A34: 304124 | B34: DEPARTAMENTO ESTADUAL DE TRANSITO | C34: 304124 | D34: 42711 | E34: R04835156390 | F34: RUA TRANCREDO NEVES 217 | G34: MACAPÁ | H34: SÃO LÁZARO | I34: AP | J34: 68909-130 | K34: BR | S34: TSR | T34: FOPU | U34: =VLOOKUP(T34,Apoio!$D$10:$E$55,2,0) -> Órgãos Públicos - PJ | AA34: =IF(Y34="","Não","Sim") -> Não | AB34: =IF(Z34="","Não","Sim") -> Não | AC34: =IF(S34="TSR","Serede","Rede Conecta") -> Serede
A35: 304172 | B35: RECEITA FEDERAL DO BRASIL - CAC | C35: 304172 | D35: 43290 | E35: R04835156390 | F35: RUA CLAUDINO BENTO DA SILVA 11 | G35: FLORIANOPOLIS | H35: CENTRO | I35: SC | J35: 88010-135 | K35: BR | S35: TSR | T35: FOPU | U35: =VLOOKUP(T35,Apoio!$D$10:$E$55,2,0) -> Órgãos Públicos - PJ | AA35: =IF(Y35="","Não","Sim") -> Não | AB35: =IF(Z35="","Não","Sim") -> Não | AC35: =IF(S35="TSR","Serede","Rede Conecta") -> Serede
A36: 304173 | B36: PREVIDENCIA SOCIAL - AGENCIA | C36: 304173 | D36: 43290 | E36: R04835156390 | F36: RUA FELIPE SCHMIDT 331 | G36: FLORIANOPOLIS | H36: CENTRO | I36: SC | J36: 88010-000 | K36: BR | L36: (48) 3298-8000 | S36: TSR | T36: FOPU | U36: =VLOOKUP(T36,Apoio!$D$10:$E$55,2,0) -> Órgãos Públicos - PJ | AA36: =IF(Y36="","Não","Sim") -> Não | AB36: =IF(Z36="","Não","Sim") -> Não | AC36: =IF(S36="TSR","Serede","Rede Conecta") -> Serede
A37: 304174 | B37: SECRETARIA DA RECEITA FEDERAL | C37: 304174 | D37: 43290 | E37: R04835156390 | F37: AVENIDA PRESIDENTE CARLOS, 375 | G37: RIO DE JANEIRO | H37: CENTRO | I37: RJ | J37: 20020-001 | K37: BR | S37: TSR | T37: FOPU | U37: =VLOOKUP(T37,Apoio!$D$10:$E$55,2,0) -> Órgãos Públicos - PJ | AA37: =IF(Y37="","Não","Sim") -> Não | AB37: =IF(Z37="","Não","Sim") -> Não | AC37: =IF(S37="TSR","Serede","Rede Conecta") -> Serede
A38: 304175 | B38: INSTITUTO NACIONAL DO SEGURO SOCIAL | C38: 304175 | D38: 43290 | E38: R04835156390 | F38: RUA PEDRO LESSA | G38: RIO DE JANEIRO | H38: CENTRO | I38: RJ | J38: 20030-030 | K38: BR | S38: TSR | T38: FOPU | U38: =VLOOKUP(T38,Apoio!$D$10:$E$55,2,0) -> Órgãos Públicos - PJ | AA38: =IF(Y38="","Não","Sim") -> Não | AB38: =IF(Z38="","Não","Sim") -> Não | AC38: =IF(S38="TSR","Serede","Rede Conecta") -> Serede
A39: 205294 | B39: MUNICIPIO DE CAMPOS DOS GOYTACAZES | C39: 205294 | D39: 43291 | E39: R04835156390 | F39: R PONCIANO DE AZEVEDO FURTADO 47 | G39: CAMPOS DOS GOYTACAZES | H39: PARQUE SANTO AMARO | I39: RJ | J39: 28030-045 | K39: BR | S39: TSR | T39: FPRE | U39: =VLOOKUP(T39,Apoio!$D$10:$E$55,2,0) -> Prefeituras - PJ | AA39: =IF(Y39="","Não","Sim") -> Não | AB39: =IF(Z39="","Não","Sim") -> Não | AC39: =IF(S39="TSR","Serede","Rede Conecta") -> Serede
A40: 205295 | B40: MUNICIPIO DE VOLTA REDONDA | C40: 205295 | D40: 43291 | E40: R04835156390 | F40: PC SAVIO GAMA 53 | G40: VOLTA REDONDA | H40: ATERRADO | I40: RJ | J40: 27215-620 | K40: BR | S40: TSR | T40: FPRE | U40: =VLOOKUP(T40,Apoio!$D$10:$E$55,2,0) -> Prefeituras - PJ | AA40: =IF(Y40="","Não","Sim") -> Não | AB40: =IF(Z40="","Não","Sim") -> Não | AC40: =IF(S40="TSR","Serede","Rede Conecta") -> Serede
...

Sheet Apoio
C3: Utilizados hoje | D3: FSDI | E3: Serviços
D4: FFUN | E4: Funcionários
D5: FPFZ | E5: PF
D6: FPRE | E6: Prefeitura
D10: 1 | E10: Fornecedor
D11: 2 | E11: Fornecedor de mercadoria
D12: 3 | E12: Recebedor alternativo pgto.
D13: 4 | E13: Emissor da fatura
D14: 5 | E14: Agente de frete
D15: 6 | E15: Endereço de pedido
D16: 7 | E16: Centros
D17: 12 | E17: Nó de hierarquia
D18: 100 | E18: Fornecedor-centro de distrib.
D19: CPD | E19: Fornecedores CD (atrib.int.nº)
D20: CPDL | E20: Fornecedores CD (atrib.ext.nº)
D21: DARL | E21: Mutuante
D22: FCON | E22: Consultorias - PJ
D23: FESA | E23: Segurança e Monitoramento - PJ
D24: FEST | E24: Fornecedor Estrangeiro
D25: FEXM | E25: Exames médicos - PJ
D26: FFRT | E26: Fretes - PJ
D27: FFUN | E27: Funcionários - PF
D28: FHTP | E28: Hotéis e Pousadas - PJ
D29: FLEP | E29: Locação de Equipamentos - PJ
D30: FLVE | E30: Locação de veículos - PJ
... D55: YPFI | E55: Fornecedor Pessoa Física
