Workbook
Name emailLink: MTZ_Steakholders!$J$2

Sheet MTZ_Steakholders
A1: NOME N1 | B1: E-mail | C1: NOME N2 | D1: E-mail | E1: NOME N3 | F1: E-mail | G1: GESTOR IMEDIATO | H1: E-mail | I1: PONTO FOCAL | J1: E-mail | K1: Área
A2: Duilio De Novaes Alves | B2: duilio.alves@oi.net.br | G2: Kamila De Vasconcelos Vieira | H2: kamila.vieira@oi.net.br | I2: Alana de Souza Silva | J2: alana.silva@oi.net.br | K2: Riscos/Controles
A3: Adriana da Cunha Costa | B3: adriana.costa@oi.net.br | C3: Viviane Prado Perdigao | D3: viviane.perdigao@oi.net.br | G3: Jorge Luiz Da Silva Correia | H3: jorgelsc@oi.net.br | K3: Regulatório
A4: Adriana da Cunha Costa | B4: adriana.costa@oi.net.br | C4: Viviane Prado Perdigao | D4: viviane.perdigao@oi.net.br | G4: Carlos Vasconcelos Galvão | H4: carlosgalvao@oi.net.br | I4: Mayara Florencio Alves Rios | J4: mayara.rios@oi.net.br | K4: Regulatório
A5: Adriana da Cunha Costa | B5: adriana.costa@oi.net.br | C5: Viviane Prado Perdigao | D5: viviane.perdigao@oi.net.br | G5: Carlos Vasconcelos Galvão | H5: carlosgalvao@oi.net.br | I5: Adilson de Souza e Silva | J5: adilson.souza@oi.net.br | K5: Regulatório
A6: Adriana da Cunha Costa | B6: adriana.costa@oi.net.br | C6: Viviane Prado Perdigao | D6: viviane.perdigao@oi.net.br | G6: Carlos Vasconcelos Galvão | H6: carlosgalvao@oi.net.br | I6: Liliane Marins Diniz | J6: liliane.diniz@oi.net.br | K6: Regulatório
A7: Adriana da Cunha Costa | B7: adriana.costa@oi.net.br | C7: Viviane Prado Perdigao | D7: viviane.perdigao@oi.net.br | G7: Carlos Vasconcelos Galvão | H7: carlosgalvao@oi.net.br | I7: Paulo Erny Souza De Freitas | J7: pfreitas@oi.net.br | K7: Regulatório
A8: Adriana da Cunha Costa | B8: adriana.costa@oi.net.br | C8: Viviane Prado Perdigao | D8: viviane.perdigao@oi.net.br | G8: Carlos Vasconcelos Galvão | H8: carlosgalvao@oi.net.br | I8: Sandro Esteves Pires Martins | J8: sandro.martins@oi.net.br | K8: Regulatório
A9: Adriana da Cunha Costa | B9: adriana.costa@oi.net.br | C9: Viviane Prado Perdigao | D9: viviane.perdigao@oi.net.br | G9: Mariana Oliveira Massuh Doher | H9: mariana.doher@oi.net.br | I9: Monica Cristina Felizardo Vasconcellos Dos Anjos | J9: monica.anjos@oi.net.br | K9: Regulatório
A10: Adriana da Cunha Costa | B10: adriana.costa@oi.net.br | C10: Viviane Prado Perdigao | D10: viviane.perdigao@oi.net.br | G10: Maria Margarete da Rocha | H10: maria.rocha@oi.net.br | K10: Regulatório
A11: Adriana da Cunha Costa | B11: adriana.costa@oi.net.br | C11: Eduardo Levy Cardoso Moreira | D11: eduardo.levy@oi.net.br | G11: Ildeu Randolfo Borges Junior | H11: ildeu.borges@oi.net.br | K11: Regulatório
A12: Rogerio Takayanagi | B12: rogerio.t@oi.net.br | C12: Luiz Henrique Soares Rosa | D12: luiz.rosa@oi.net.br | G12: Alessandro de Magalhães Barbosa | H12: alessandro.magalhaes@oi.net.br | I12: Charlene Santino da Silva | J12: charlene.silva@oi.net.br | K12: M&A
A13: Rogerio Takayanagi | B13: rogerio.t@oi.net.br | C13: Luiz Henrique Soares Rosa | D13: luiz.rosa@oi.net.br | G13: Alessandro de Magalhães Barbosa | H13: alessandro.magalhaes@oi.net.br | I13: Francisco Anderson Pereira De Paiva | J13: francisco.paiva@oi.net.br | K13: M&A
A14: Rogerio Takayanagi | B14: rogerio.t@oi.net.br | C14: Luiz Henrique Soares Rosa | D14: luiz.rosa@oi.net.br | G14: Alessandro de Magalhães Barbosa | H14: alessandro.magalhaes@oi.net.br | I14: Nathalia Piltz Correa | J14: nathalia.correa@oi.net.br | K14: M&A
A15: Rogerio Takayanagi | B15: rogerio.t@oi.net.br | C15: Luiz Henrique Soares Rosa | D15: luiz.rosa@oi.net.br | G15: Eduardo Reis Beraldo | H15: eduardo.beraldo@oi.net.br | I15: Viviane De Medeiros Calaca Gomes | J15: viviane.calaca@oi.net.br | K15: M&A
A16: Rogerio Takayanagi | B16: rogerio.t@oi.net.br | C16: Luiz Henrique Soares Rosa | D16: luiz.rosa@oi.net.br | G16: Eduardo Reis Beraldo | H16: eduardo.beraldo@oi.net.br | I16: Thais Hiromi Nakazone | J16: thais.nakazone@oi.net.br | K16: M&A
A17: Rogerio Takayanagi | B17: rogerio.t@oi.net.br | C17: Luiz Henrique Soares Rosa | D17: luiz.rosa@oi.net.br | G17: Eduardo Reis Beraldo | H17: eduardo.beraldo@oi.net.br | I17: Thiago Marcos Da Silva Barbosa | J17: thiagobarbosa@oi.net.br | K17: M&A
A18: Rogerio Takayanagi | B18: rogerio.t@oi.net.br | C18: Elly Resende Silva | D18: elly.resende@oi.net.br | G18: Karina Duprat Fortes | H18: karina.fortes@oi.net.br | K18: Transição
A19: Rogerio Takayanagi | B19: rogerio.t@oi.net.br | C19: NI | G19: Vanda Coutinho Neves De Almeida | H19: vandacna@oi.net.br | K19: Suporte Técnico
A20: Rogerio Takayanagi | B20: rogerio.t@oi.net.br | C20: NI | G20: Igor Friedrich Pinheiro | H20: igor.pinheiro@oi.net.br | K20: Suporte Técnico
A21: Cristiane Barretto Sales | B21: cristiane.barretto@oi.net.br | C21: Andre Tavares Paradizi | D21: andre.paradizi@oi.net.br | G21: Patricia Decursi Gouveia de Souza | H21: patricia.gouveia@oi.net.br | I21: Anderson Luis da Silva de Souza | J21: andersonlss@oi.net.br | K21: Controladoria
A22: Cristiane Barretto Sales | B22: cristiane.barretto@oi.net.br | C22: Andre Tavares Paradizi | D22: andre.paradizi@oi.net.br | E22: Francisco Paulo Macambira Haick | F22: francisco.haick@oi.net.br | G22: Patricia Ann Necyk | H22: pan@oi.net.br | I22: Adriana Fragoso | J22: adriana.fragoso@oi.net.br | K22: Contabilidade
A23: Cristiane Barretto Sales | B23: cristiane.barretto@oi.net.br | C23: Andre Tavares Paradizi | D23: andre.paradizi@oi.net.br | E23: Francisco Paulo Macambira Haick | F23: francisco.haick@oi.net.br | G23: Patricia Ann Necyk | H23: pan@oi.net.br | I23: Priscila Duarte De Oliveira | J23: priscila.oliveira@oi.net.br | K23: Contabilidade
A24: Cristiane Barretto Sales | B24: cristiane.barretto@oi.net.br | C24: Andre Tavares Paradizi | D24: andre.paradizi@oi.net.br | E24: Francisco Paulo Macambira Haick | F24: francisco.haick@oi.net.br | G24: Patricia Ann Necyk | H24: pan@oi.net.br | I24: Patricia Almeida | J24: patricia.maria@oi.net.br | K24: Contabilidade
A25: Cristiane Barretto Sales | B25: cristiane.barretto@oi.net.br | C25: Andre Tavares Paradizi | D25: andre.paradizi@oi.net.br | E25: Francisco Paulo Macambira Haick | F25: francisco.haick@oi.net.br | G25: Patricia Ann Necyk | H25: pan@oi.net.br | I25: Celiane Sousa Vieira | J25: celiane.vieira@oi.net.br | K25: Contabilidade
A26: Cristiane Barretto Sales | B26: cristiane.barretto@oi.net.br | C26: Andre Tavares Paradizi | D26: andre.paradizi@oi.net.br | E26: Francisco Paulo Macambira Haick | F26: francisco.haick@oi.net.br | G26: Marcelo Gomes | H26: marcelo.gomes@oi.net.br | I26: Alessandra Leandro de Oliveira | J26: alessandra.leandro@oi.net.br | K26: Contabilidade
A27: Cristiane Barretto Sales | B27: cristiane.barretto@oi.net.br | C27: Andre Tavares Paradizi | D27: andre.paradizi@oi.net.br | E27: Francisco Paulo Macambira Haick | F27: francisco.haick@oi.net.br | G27: Marcelo Gomes | H27: marcelo.gomes@oi.net.br | I27: Jonas de Azevedo Almeida | J27: jonas.almeida@oi.net.br | K27: Contabilidade
A28: Cristiane Barretto Sales | B28: cristiane.barretto@oi.net.br | C28: Andre Tavares Paradizi | D28: andre.paradizi@oi.net.br | E28: Francisco Paulo Macambira Haick | F28: francisco.haick@oi.net.br | G28: Marcelo Gomes | H28: marcelo.gomes@oi.net.br | I28: Mateus Pacheco De Oliveira Santos | J28: mateussantos@oi.net.br | K28: Contabilidade
A29: Cristiane Barretto Sales | B29: cristiane.barretto@oi.net.br | C29: Andre Tavares Paradizi | D29: andre.paradizi@oi.net.br | E29: Francisco Paulo Macambira Haick | F29: francisco.haick@oi.net.br | G29: Marcelo Gomes | H29: marcelo.gomes@oi.net.br | I29: Lilian Carmen de Freitas | J29: lilian.freitas@oi.net.br | K29: Contabilidade
A30: Cristiane Barretto Sales | B30: cristiane.barretto@oi.net.br | C30: Andre Tavares Paradizi | D30: andre.paradizi@oi.net.br | E30: Priscila Bittencourt Martins Mannino | F30: priscila.mannino@oi.net.br | K30: Planejamento Digital
A31: Cristiane Barretto Sales | B31: cristiane.barretto@oi.net.br | C31: Pedro De Andrade Franca | D31: pedro.franca@oi.net.br | E31: Philippe Reis Brasil | F31: pedro.franca@oi.net.br | I31: Elisabete de Sousa Ribeiro | J31: elisabete.ribeiro@oi.net.br | K31: Tesouraria
A32: Cristiane Barretto Sales | B32: cristiane.barretto@oi.net.br | C32: Pedro De Andrade Franca | D32: pedro.franca@oi.net.br | E32: Carolina Gava | F32: carolina.gava@oi.net.br | I32: Daniele Morais Silva Gouvea | J32: daniele.gouvea@oi.net.br | K32: Tesouraria
A33: Cristiane Barretto Sales | B33: cristiane.barretto@oi.net.br | C33: Pedro De Andrade Franca | D33: pedro.franca@oi.net.br | E33: Liege Casqueiro | F33: liege.casqueiro@oi.net.br | I33: Camila Costa da Silva | J33: camilacosta@oi.net.br | K33: Seguros
A34: Cristiane Barretto Sales | B34: cristiane.barretto@oi.net.br | C34: Andre Tavares Paradizi | D34: andre.paradizi@oi.net.br | E34: Liege Casqueiro | F34: liege.casqueiro@oi.net.br | I34: Leonardo Bauer Marinho | J34: leonardo.marinho@oi.net.br | K34: Seguros
A35: Cristiane Barretto Sales | B35: cristiane.barretto@oi.net.br | C35: Pedro De Andrade Franca | D35: pedro.franca@oi.net.br | E35: Ana Kelly Da Silva Carneiro | F35: ana.carneiro@oi.net.br | G35: Manuela Barros de Sá Grande | H35: manuela.grande@oi.net.br | I35: Fernanda Beserra De Almeida | J35: fernanda.almeida@oi.net.br | K35: CAP
A36: Cristiane Barretto Sales | B36: cristiane.barretto@oi.net.br | C36: Pedro De Andrade Franca | D36: pedro.franca@oi.net.br | E36: Eduardo Streit | F36: eduardo.streit@oi.net.br | K36: Caixa
A37: Cristiane Barretto Sales | B37: cristiane.barretto@oi.net.br | C37: Flavia Sobreira Casali Lima Bastos | D37: flaviacasali@oi.net.br | G37: Paulo Roberto Salgueiro Vidal | H37: paulo.vidal@oi.net.br | I37: Cristiana Teixeira de Luna Freire | J37: cristiana.freire@oi.net.br | K37: Tributos/Fiscal
B38: cristiane.barretto@oi.net.br | C38: Flavia Sobreira Casali Lima Bastos | D38: flaviacasali@oi.net.br | G38: Paulo Roberto Salgueiro Vidal | H38: paulo.vidal@oi.net.br | I38: Marcos Carneiro Pereira | J38: marcospereira@oi.net.br | K38: Tributos/Fiscal
A39: Cristiane Barretto Sales | B39: cristiane.barretto@oi.net.br | C39: Flavia Sobreira Casali Lima Bastos | D39: flaviacasali@oi.net.br | G39: Erika Braga | H39: erika.braga@oi.net.br | I39: Elaine Vermil Lima Santiago | J39: elaine.santiago@oi.net.br | K39: Tributos/Fiscal
A40: Cristiane Barretto Sales | B40: cristiane.barretto@oi.net.br | C40: Flavia Sobreira Casali Lima Bastos | D40: flaviacasali@oi.net.br | G40: Erika Braga | H40: erika.braga@oi.net.br | I40: Christie Ramos Opytaciano Dos Santos | J40: christie.santos@oi.net.br | K40: Tributos/Fiscal
...

Sheet Lista Única Pessoas
A1: Nomes | B1: E-mails | C1: Área | D1: Nivel | E1: Incluir na reunião | F1: Enviar Material | I1: 1
A2: Adilson de Souza e Silva | B2: adilson.souza@oi.net.br | C2: =VLOOKUP(A2,MTZ_Steakholders!$I$2:$K$123,3,0) -> Regulatório | D2: Ponto Focal | F2: N | I2: 2
A3: Adriana da Cunha Costa | B3: adriana.costa@oi.net.br | C3: =VLOOKUP(A3,MTZ_Steakholders!$A$2:$K$123,11,0) -> Regulatório | D3: N1 | F3: N | I3: 2
A4: Adriana Fragoso | B4: adriana.fragoso@oi.net.br | C4: =VLOOKUP(A4,MTZ_Steakholders!$I$2:$K$123,3,0) -> Contabilidade | D4: Ponto Focal | F4: N
A5: Adriana Velhote | B5: adriana.velhote@oi.net.br | C5: =VLOOKUP(A5,MTZ_Steakholders!$G$2:$K$123,5,0) -> Jur Consumidor | D5: Gestor Imediato | F5: S
A6: Adriano Andrey Israel | B6: adriano.israel@oi.net.br | C6: =VLOOKUP(A6,MTZ_Steakholders!$G$2:$K$123,5,0) -> Patrimonio | D6: Gestor Imediato | F6: S
A7: Alana de Souza Silva | B7: alana.silva@oi.net.br | C7: =VLOOKUP(A7,MTZ_Steakholders!$I$2:$K$123,3,0) -> Riscos/Controles | D7: Ponto Focal | F7: N
A8: Alessandra Leandro de Oliveira | B8: alessandra.leandro@oi.net.br | C8: =VLOOKUP(A8,MTZ_Steakholders!$I$2:$K$123,3,0) -> Contabilidade | D8: Ponto Focal | F8: N
A9: Alessandra Lima Ramos de Mattos Benevides | B9: alessandra.benevides@oi.net.br | C9: =VLOOKUP(A9,MTZ_Steakholders!$I$2:$K$123,3,0) -> Jur Tributario | D9: Ponto Focal | F9: N
A10: Alessandra Perrelli | B10: alessandra.perrelli@oi.net.br | C10: =VLOOKUP(A10,MTZ_Steakholders!$G$2:$K$123,5,0) -> Data Analytics | D10: Gestor Imediato | F10: S
A11: Alessandro de Magalhães Barbosa | B11: alessandro.magalhaes@oi.net.br | C11: =VLOOKUP(A11,MTZ_Steakholders!$G$2:$K$123,5,0) -> M&A | D11: Gestor Imediato | F11: S
A12: Alessandro Luiz Varme Dias | B12: alessandro.varme@oi.net.br | C12: =VLOOKUP(A12,MTZ_Steakholders!$E$2:$K$123,7,0) -> Fraude | D12: N3 | F12: S
A13: Alexandre De Souza Soares | B13: alexandre.ssoares@oi.net.br | C13: =VLOOKUP(A13,MTZ_Steakholders!$I$2:$K$123,3,0) -> Sistemas TI | D13: Ponto Focal | F13: N
A14: Alexandre Luiz Furtado Domingues | B14: alexandre.domingues@oi.net.br | C14: =VLOOKUP(A14,MTZ_Steakholders!$C$2:$K$123,9,0) -> Infra e Operações TI | D14: N2 | F14: S
A15: Altevo Carlos De Sa Volotao | B15: altevo.volotao@oi.net.br | C15: =VLOOKUP(A15,MTZ_Steakholders!$E$2:$K$123,7,0) -> Faturamento | D15: N3 | F15: S
A16: Ana Carolina Sarno De Mattos | B16: anamattos@oi.net.br | C16: =VLOOKUP(A16,MTZ_Steakholders!$E$2:$K$123,7,0) -> Infra e Operações TI | D16: N3 | F16: S
A17: Ana Cristina Guimaraes Murad | B17: anamurad@oi.net.br | C17: =VLOOKUP(A17,MTZ_Steakholders!$G$2:$K$123,5,0) -> Empresarial | D17: Gestor Imediato | F17: S
A18: Ana Kelly Da Silva Carneiro | B18: ana.carneiro@oi.net.br | C18: =VLOOKUP(A18,MTZ_Steakholders!$E$2:$K$123,7,0) -> CAP | D18: N3 | F18: S
A19: Ana Luiza Cunha E Silva Jorge | B19: ana.luiza@oi.net.br | C19: =VLOOKUP(A19,MTZ_Steakholders!$I$2:$K$123,3,0) -> Sistemas TI | D19: Ponto Focal | F19: N
A20: Ana Thereza Silva Miguelote | B20: ana.miguelote@oi.net.br | C20: =VLOOKUP(A20,MTZ_Steakholders!$C$2:$K$123,9,0) -> Energia | D20: N2 | F20: S
A21: Anderson Luis da Silva de Souza | B21: andersonlss@oi.net.br | C21: =VLOOKUP(A21,MTZ_Steakholders!$I$2:$K$123,3,0) -> Controladoria | D21: Ponto Focal | F21: N
A22: Anderson Luiz Fernandes Esteves | B22: anderson.esteves@oi.net.br | C22: =VLOOKUP(A22,MTZ_Steakholders!$G$2:$K$123,5,0) -> Empresarial | D22: Gestor Imediato | F22: S
A23: Andre Pereira Lopes | B23: andrelopes@oi.net.br | C23: =VLOOKUP(A23,MTZ_Steakholders!$I$2:$K$123,3,0) -> Fraude | D23: Ponto Focal | F23: N
A24: Andre Tavares Paradizi | B24: andre.paradizi@oi.net.br | C24: =VLOOKUP(A24,MTZ_Steakholders!$C$2:$K$123,9,0) -> Controladoria | D24: N2 | F24: S
A25: Antonio Carlos Da Silva Gomes | B25: antonio.silva.gomes@oi.net.br | C25: =VLOOKUP(A25,MTZ_Steakholders!$I$2:$K$123,3,0) -> Sistemas TI | D25: Ponto Focal | F25: N
A26: Ariane Fonseca Vieira | B26: ariane.vieira@oi.net.br | C26: =VLOOKUP(A26,MTZ_Steakholders!$C$2:$K$123,9,0) -> RH - Relac. Trab., Seg. | D26: N2 | F26: S
A27: Aroldo Candido Junior | B27: aroldo.junior@oi.net.br | C27: =VLOOKUP(A27,MTZ_Steakholders!$I$2:$K$123,3,0) -> Tributos/Fiscal | D27: Ponto Focal | F27: N
A28: Barbara Coelho Martinho | B28: barbara.martinho@oi.net.br | C28: =VLOOKUP(A28,MTZ_Steakholders!$G$2:$K$123,5,0) -> Comunicação | D28: Gestor Imediato | F28: S
A29: Barbara Erthal Pinheiro | B29: barbara.erthal@oi.net.br | C29: =VLOOKUP(A29,MTZ_Steakholders!$G$2:$K$123,5,0) -> Jur Societário | D29: Gestor Imediato | F29: S
A30: Bernardo Maturo Ieno | B30: bernardo.ieno@oi.net.br | C30: =VLOOKUP(A30,MTZ_Steakholders!$G$2:$K$123,5,0) -> Patrimonio | D30: Gestor Imediato | F30: S
A31: Bruno De Almeida Palombo | B31: bruno.palombo@oi.net.br | C31: =VLOOKUP(A31,MTZ_Steakholders!$G$2:$K$123,5,0) -> Data Analytics | D31: Gestor Imediato | F31: S
A32: Bruno de Sousa Oliveira | B32: bruno.sousa@oi.net.br | C32: =VLOOKUP(A32,MTZ_Steakholders!$I$2:$K$123,3,0) -> Cobrança | D32: Ponto Focal | F32: N
A33: Bruno Diehl | B33: bruno.diehl@oi.net.br | C33: =VLOOKUP(A33,MTZ_Steakholders!$C$2:$K$123,9,0) -> Sistemas TI | D33: N2 | F33: S
A34: Bruno Macedo Soares | B34: bmacedo@oi.net.br | C34: =VLOOKUP(A34,MTZ_Steakholders!$C$2:$K$123,9,0) -> PDD | D34: N2 | F34: S
A35: Caio Marcio Gusmon | B35: caio.gusmon@oi.net.br | C35: =VLOOKUP(A35,MTZ_Steakholders!$A$2:$K$123,11,0) -> Sistemas TI | D35: N1 | F35: S
A36: Camila Costa da Silva | B36: camilacosta@oi.net.br | C36: =VLOOKUP(A36,MTZ_Steakholders!$I$2:$K$123,3,0) -> Seguros | D36: Ponto Focal | F36: N
A37: Camilla Luciano Teixeira | B37: camilla.teixeira@oi.net.br | C37: =VLOOKUP(A37,MTZ_Steakholders!$I$2:$K$123,3,0) -> Contas a receber | D37: Ponto Focal | F37: N
A38: Carlos Alberto Sant Anna Lapa | B38: carlos.lapa@oi.net.br | C38: =VLOOKUP(A38,MTZ_Steakholders!$G$2:$K$123,5,0) -> Sistemas TI | D38: Gestor Imediato | F38: S
A39: Carlos Eduardo da Rocha Andrade | B39: carlos.andrade@oi.net.br> | C39: =VLOOKUP(A39,MTZ_Steakholders!$G$2:$K$123,5,0) -> RH - Remuneração, Planejamento e Gestão | D39: Gestor Imediato | F39: S
A40: Carlos Vasconcelos Galvão | B40: carlosgalvao@oi.net.br | C40: =VLOOKUP(A40,MTZ_Steakholders!$G$2:$K$123,5,0) -> Regulatório | D40: Gestor Imediato | F40: S
...

Sheet Agenda Reuniões
B2: Agenda de Reunião
A3: 1 | B3: Daily M&A | C3: 10hs
A4: 2 | B4: Weekly Executiva | C4: Qui 11hs
A5: 3 | B5: Quinzenal Executiva | C5: Qua 11hs
A6: 4 | B6: Mensal CDG
A9: Após a confirmação dos participantes, iremos propor a agenda das reuniões das frentes de trabalho.
