Workbook

Sheet Anexo A-TODOS OS SERVIÇOS (OLD)
B2: Resumo dos serviços descritos no TSA. | C2: Topicos | D2: Anexo A (MobileCo) | E2: Texto Anexo A (ClientCo) | F2: Área responsável pelo Report | G2: Pessoa responsável pelo Report | H2: Áreas impactadas | I2: Anotações | J2: Status Anexo A | K2: Nome da VP | L2: N1 | M2: N2 | N2: N3 | O2: N4/ Consultor
B3: Customer data and offer management​ | C3: Reajuste de Planos e Serviços ou ajustes de portfólio (inclusão, exclusão ou alterações) ​ | D3: Sob demanda, a Oi deverá desenvolver sistemicamente as inclusões, exclusões, ou alterações de preço (e não de dinâmica) das ofertas dentro das práticas e volumes atuais da Oi de forma a reenquadrar portfólio/clientes. Envolve implementar, testar e garantir a qualidade em toda cadeia (Front end, Fatura, contabilização, etc.) podendo ser acompanhado pelas Compradoras. Políticas comerciais, regras, valores e features serão solicitadas pelas Compradoras e serão avaliadas pela Oi quanto a viabilidade técnica, financeira, legal e regulatória. As alterações implantadas terão report para fins de acompanhamento do solicitante. Qualquer modificação que demande Capex, deverá ser reembolsada e não estará coberta pelo cap do Contrato. | E3: Sob demanda, a Oi deverá desenvolver sistemicamente as inclusões, exclusões, ou alterações de preço (e não de dinâmica) das ofertas dentro das práticas e volumes atuais da Oi de forma a reenquadrar portfólio/clientes. Envolve implementar, testar e garantir a qualidade em toda cadeia (Front end, Fatura, contabilização, etc.) podendo ser acompanhado pelas Compradoras. Políticas comerciais, regras, valores e features serão solicitadas pelas Compradoras e serão avaliadas pela Oi quanto a viabilidade técnica, financeira, legal e regulatória. As alterações implantadas terão report para fins de acompanhamento do solicitante. Qualquer modificação que demande Capex, deverá ser reembolsada e não estará coberta pelo cap do Contrato. | F3: Produtos | G3: Felícia | H3: Varejo e Empresarial; Faturamento | J3: EXCLUIR ESTE ITEM | K3: Oi Fibra | L3: Fabricio Bindi <fabricio.bindi@oi.net.br> | M3: Luis Filipe Meira <lfmeira@oi.net.br> | N3: Renato Elias <renato.elias@oi.net.br> | O3: Felicia Daquino Nonato Rosetti <felicia@oi.net.br>
B4: Customer data and offer management​ | C4: BI sendo prestado pela OI​ | D4: Garantir acesso as Compradoras das informações necessárias para tomada de decisões referente aos processos determinados pelo Contrato até a data de migração dos clientes de acordo com o SLA, meio, formato e tecnologia a ser definido entre as partes, respeitando as capacidades tecnológicas e regulações vigentes. | E4: A Oi se compromete a, sob demanda, compartilhar informações já disponíveis ou fornecer detalhamento de viabilidade técnica, prazo e custo incremental de novos desenvolvimentos, para apoio à tomada de decisões referentes aos processos determinados pelo Contrato durante o prazo de vigência do TSA, levando em consideração SLA, meio, formato e tecnologia a serem definidos entre as partes, respeitando as capacidades tecnológicas e regulações vigentes. | F4: DA | G4: Bruno Palombo | H4: Data Analytics | I4: Bruno Palombo: refinamento de escopo detalhando cenário de solicitação de novos desenvolvimentos com custo incremental | J4: CONCLUÍDO | K4: Tecnologia | L4: Caio Marcio Gusmon <caio.gusmon@oi.net.br> | M4: Ulisses Fonseca Alves <ulisses.alves@oi.net.br> | N4: Bruno Palombo <bruno.palombo@oi.net.br> | O4: -
B5: Customer data and offer management​ | C5: Consultoria tributária e atendimento à fiscalização | D5: A Oi se compromete a avaliar atendimento à novas demandas legais, fiscais e regulatórias, efetuadas posteriormente à assinatura do Contrato, avaliando viabilidade técnica, riscos, prazos legais/regulatórios e custo incremental. | E5: A Oi se compromete a avaliar novas demandas legais, fiscais e tributárias, criadas/instituídas posteriormente à assinatura do Contrato (durante o período do TSA), avaliando viabilidade técnica, riscos, prazos legais e custo incremental. O custo, pelos desenvolvimentos necessários, serão arcados e/ou reembolsamos pela compradora, a depender do que ficar combinado no contrato. Não há como prever, de antemão, quais seriam esses custos, já que não sabemos quais novas obrigações poderiam ser criadas. Ademais, especificamente ao atendimento à fiscalização tributária, a Oi se compromete em garantir a disposnibilidação da documentação suporte conforme AS IS para atendimento às notificações recebidas pelo Jurídico Tributário. | F5: Jurídico Tributário | G5: Julia Villares e Alessandra Lima | H5: Jur. Tributário | I5: Premissa utilizada pelo Jurídicotributário para elaboração do texto da ClientCo (Alessandra): Tendo em vista que nos foi dito em reunião que a Oi vai se comprometer com as ClientCo a avaliar e levantar os custos para o atendimento das novas demandas legais, relativas a temas fiscais e tributários, que venham a ser instituídas/criadas posteriormente à assinatura do Contrato (desde o closing e durante o período de vigência do TSA). | J5: CONCLUÍDO | K5: Jurídico | L5: Thalles Eduardo Silva Gracelacio Da Paixao <thalles.paixao@oi.net.br> | M5: Fernando Raposo Franco <fernando.franco@oi.net.br> | N5: Pedro Rique Nepomuceno <pedro.nepomuceno@oi.net.br> | O5: Julia Villares Torres <julia.torres@oi.net.br>
B6: Customer data and offer management​ | C6: Consultoria cível estratégico | D6: Novi item | E6: A Oi se compromete a prestar consultoria jurídica ou viabilizar a interface dos integrantes do grupo com a área jurídica impactada. | F6: Jurídico Cível Estratégico | G6: Luiz Felipe Vargas | J6: CONCLUÍDO | K6: Jurídico | L6: Thalles Eduardo Silva Gracelacio Da Paixao <thalles.paixao@oi.net.br> | M6: Fernando Raposo Franco <fernando.franco@oi.net.br> | N6: Luiz Felipe Neves Do Couto Vargas <luizf.vargas@oi.net.br>
B7: Customer data and offer management​ | C7: Ajustes sistêmicos para Regulatório | D7: A Oi se compromete a avaliar atendimento à novas demandas legais, fiscais e regulatórias, efetuadas posteriormente à assinatura do Contrato, avaliando viabilidade técnica, riscos, prazos legais/regulatórios e custo incremental. | E7: A Oi se compromete a avaliar atendimento à novas demandas legais, fiscais e regulatórias, efetuadas posteriormente à assinatura do Contrato, avaliando viabilidade técnica, riscos, prazos legais/regulatórios e custo incremental. | F7: Regulatório | G7: Carlos Galvão/ Dennis | H7: Regulatório | J7: CONCLUÍDO | K7: Regulatório e Institucional | L7: Adriana Da Cunha Costa <adriana.costa@oi.net.br> | M7: Adriana Da Cunha Costa <adriana.costa@oi.net.br> | N7: Carlos Vasconcelos Galvao <carlosgalvao@oi.net.br> | O7: -
B8: Admin personnel​ | C8: Payroll administration​ | D8: - Tratar os dados necessários para cálculo da folha de pagamento, calcular a folha de pagamento, pagar os respectivos impostos e demais deduções. - Quanto a migração das informações dos colaboradores a serem transferidos (FTEs) para a Claro, essa também considera a migração em duas fases - a primeira com os dados dos colaboradores e uma segunda fase para migração dos dados históricos. Dessa forma, a Claro ficará com todas as informações em compliance com as regulamentações. | E8: "- Tratar os dados necessários para cálculo da folha de pagamento, calcular a folha de pagamento, pagar os respectivos impostos e demais deduções. - Quanto a migração das informações dos colaboradores a serem transferidos (FTEs) para as compradoras, essa também considera a migração de todos os dados dos colaboradores e uma única fase. | F8: RH | G8: Ricardo | H8: RH | I8: O ponto focal do RH para auxiliar as áreas a mensurar os custos dos profissionais envolvidos no TSA será o Carlos Eduardo da Rocha | J8: EXCLUIR ESTE ITEM | K8: Pessoas & Cultura | L8: Marcos Aurelio Freire Mendes <marcos.mendes@oi.net.br> | M8: Ricardo Goulart <rgoulart@oi.net.br> | N8: Carlos Eduardo Da Rocha Andrade <carlos.andrade@oi.net.br>; Jussara Petra Rocha <jussara.rocha@oi.net.br>; Valeria Da Conceicao Braga <valeria.braga@oi.net.br> | O8: -
B9: Admin personnel​ | C9: Benefits administration​ | D9: - Manutenção da base e gestão dos benefícios (plano médico, plano odontológico, seguro de vida, vale transporte, previdência privada, auxílio creche, auxílio medicamentos e tíquete refeição/alimentação garantindo a disponibilidade e qualidade dos mesmos; - Faturar a utilização total dos benefícios, parcela da coparticipação (ainda não descontada) e utilização total (custo empresa) pós closing | E9: "- Manutenção da base e gestão dos benefícios (plano médico, plano odontológico, seguro de vida, vale transporte, previdência privada, auxílio creche, auxílio medicamentos e tíquete refeição/alimentação garantindo a disponibilidade e qualidade dos mesmos; - Faturar as compradoras toda a utilização de benefícios, parcela da coparticipação (ainda não descontada) e utilização total (custo empresa) pós closing, durante todo o período do TSA. | F9: RH | G9: Ricardo | H9: RH | I9: O ponto focal do RH para auxiliar as áreas a mensurar os custos dos profissionais envolvidos no TSA será o Carlos Eduardo da Rocha | J9: EXCLUIR ESTE ITEM | K9: Pessoas & Cultura | L9: Marcos Aurelio Freire Mendes <marcos.mendes@oi.net.br> | M9: Ricardo Goulart <rgoulart@oi.net.br> | N9: Carlos Eduardo Da Rocha Andrade <carlos.andrade@oi.net.br>; Jussara Petra Rocha <jussara.rocha@oi.net.br>; Valeria Da Conceicao Braga <valeria.braga@oi.net.br> | O9: -
B10: Bill-to-cash​ | C10: Execução de ciclos de Billings​ | D10: - A Oi deverá executar o processo de faturamento de terminais móveis, mantendo os sistemas, regras e processos atuais, até a migração total desses clientes. - Execução de todos os ciclos de billings (majoritários e minoritários) em todos os sistemas de faturamento existentes no parque de TI. - Execução dos ciclos de billing para processo de Cobilling junto as operadoras (Entrante e Sainte). - Resolução dos problemas encontrados durante o processamento. | E10: - A Oi deverá executar o processo de faturamento de terminais fibra, mantendo os sistemas, regras e processos atuais, até a migração total desses clientes. - Execução de todos os ciclos de billings (majoritários e minoritários) em todos os sistemas de faturamento existentes no parque de TI. - Resolução dos problemas encontrados durante o processamento. | F10: Faturamento | G10: Monica | H10: Faturamento | J10: CONCLUÍDO | K10: Finanças e Relações com investidores | L10: Cristiane Barretto Sales <cristiane.barretto@oi.net.br> | M10: Bruno Macedo Soares <bmacedo@oi.net.br> | N10: Monica Sant Anna Paetzoldt <monica.paetzoldt@oi.net.br> | O10: -
B11: Bill-to-cash​ | C11: Tarifação de chamadas, dados e eventos ​ | D11: A Oi irá executar o processo de tarifação de chamadas/ eventos/ SVAs/ consumo excedentes de terminais móveis, mantendo os sistemas, regras, processos e produtos e ofertas atuais, até a migração total desses clientes. - O tráfego do CSP das Compradoras continuará a ser tratado como Cobilling - Execução dos processos de tarifação em todos os sistemas de tarifação (chamadas, eventos e consumos de dados) realizados pelos clientes do segmento móvel. - Contemplar o processo de tarifação para chamadas de outras operadoras (Entrante e Sainte) e também Parcerias/CO faturamento “doações – SVAs”, garantindo o envio e recepção de chamadas. - Resolução dos problemas encontrados durante o processamento. | E11: - Realização do processo de Tarifação de Voz, SVA e 0500 mantendo os sistemas, regras, processos e produtos e ofertas atuais, até a migração total desses clientes. - Resolução dos problemas encontrados durante o processamento. | F11: Tráfego | G11: Marcus Vinícius | H11: Faturamento// Tarifação e Repasse | J11: CONCLUÍDO | K11: Finanças e Relações com investidores | L11: Cristiane Barretto Sales <cristiane.barretto@oi.net.br> | M11: Bruno Macedo Soares <bmacedo@oi.net.br> | N11: Altevo Carlos De Sa Volotao <altevo.volotao@oi.net.br> | O11: Marcus Vinicius Miguel De Oliveira <marcus.oliveira@oi.net.br>
B12: Bill-to-cash​ | C12: Emissão de termos de quitação​ | D12: - Emissão do termo de quitação referentes aos pagamentos das últimas faturas dos clientes móveis, a exceção de clientes corporativos e atacado onde a emissão será manual e sob demanda do cliente. - Resolução dos problemas encontrados durante o processamento. - Todas as pendências de emissão dos termos de quitação anteriores a data do fechamento do contrato deverão ser regularizadas. | E12: - Emissão do termo de quitação referentes aos pagamentos das últimas faturas dos clientes fibra. - Resolução dos problemas encontrados durante o processamento. - Todas as pendências de emissão dos termos de quitação anteriores a data do fechamento do contrato deverão ser regularizadas. | F12: Faturamento | G12: Monica | H12: Fatutamento/ Atendimento | J12: CONCLUÍDO | K12: Finanças e Relações com investidores | L12: Cristiane Barretto Sales <cristiane.barretto@oi.net.br> | M12: Bruno Macedo Soares <bmacedo@oi.net.br> | N12: Monica Sant Anna Paetzoldt <monica.paetzoldt@oi.net.br> | O12: -
B13: Bill-to-cash​ | C13: Validação do billings gerados - consistência, qualidade e confiabilidade ​ | D13: - A Oi irá executar o processo de validação prévia de faturas de terminais móveis, mantendo os sistemas, regras e processos atuais, até a migração total desses clientes. - Corrigir e reportar o tratamento adotado em caso de desvios identificados mantendo os sistemas, regras, processos e performance atuais, até a migração total desses clientes. -Executar as validações de consistência sobre o ciclo de billing executado. - Execução/geração dos processos de Contestação e Críticas das chamadas de cobilling e/ou Parcerias. | E13: - A Oi irá executar o processo de validação prévia de faturas de terminais fibra, mantendo os sistemas, regras e processos atuais, até a migração total desses clientes. - Corrigir e reportar o tratamento adotado em caso de desvios identificados mantendo os sistemas, regras, processos e performance atuais, até a migração total desses clientes. -Executar as validações de consistência sobre o ciclo de billing executado. | F13: Faturamento | G13: Monica | H13: Faturamento | J13: CONCLUÍDO | K13: Finanças e Relações com investidores | L13: Cristiane Barretto Sales <cristiane.barretto@oi.net.br> | M13: Bruno Macedo Soares <bmacedo@oi.net.br> | N13: Monica Sant Anna Paetzoldt <monica.paetzoldt@oi.net.br> | O13: -
B14: Bill-to-cash​ | C14: Disponibilização de faturas online e customizadas ​ | D14: - Oi irá disponibilizar as faturas de terminais móveis, mantendo os sistemas, regras e processos atuais, até a migração total desses clientes, nos formatos e layout atuais (online e customizadas) para clientes varejo, empresarial e corporativos. - Carga dos spools faturados nas ferramentas que disponibilizam online os documentos de faturamento. - Resolução dos problemas encontrados durante o processamento. - Eventuais necessidades de alterações deverão ser discutidas em relação à custo e prazo. | E14: - Oi irá disponibilizar as faturas de terminais fibra, mantendo os sistemas, regras e processos atuais, até a migração total desses clientes, nos formatos e layout atuais (online e customizadas) para clientes varejo e empresarial. - Carga dos spools faturados nas ferramentas que disponibilizam online os documentos de faturamento. - Resolução dos problemas encontrados durante o processamento. - Eventuais necessidades de alterações deverão ser discutidas em relação à custo e prazo. | F14: Faturamento | G14: Monica | H14: Fatutamento/ Atendimento | J14: CONCLUÍDO | K14: Finanças e Relações com investidores | L14: Cristiane Barretto Sales <cristiane.barretto@oi.net.br> | M14: Bruno Macedo Soares <bmacedo@oi.net.br> | N14: Monica Sant Anna Paetzoldt <monica.paetzoldt@oi.net.br> | O14: -
B15: Bill-to-cash​ | C15: Envio dos spools para as print centers ​ | D15: - Oi irá disponibilizar os spools de faturas de terminais móveis para as print centers atuais da Oi (e remunerar os print centers), mantendo os sistemas, regras e processos atuais, até a migração total desses clientes, nos formatos e layout atuais (online e customizadas) para clientes varejo, empresarial e corporativos. - Conferência do faturamento gerado e consistências cadastrais. - Disponibilização dos documentos para as empresas de postagem. | E15: - Oi irá disponibilizar os spools de faturas de terminais fibra para as print centers atuais da Oi (e remunerar os print centers), mantendo os sistemas, regras e processos atuais, até a migração total desses clientes, nos formatos e layout atuais (online e customizadas) para clientes varejo e empresarial. - Conferência do faturamento gerado e consistências cadastrais. - Disponibilização dos documentos para as empresas de postagem. | F15: Faturamento | G15: Monica | H15: Faturamento | J15: CONCLUÍDO | K15: Finanças e Relações com investidores | L15: Cristiane Barretto Sales <cristiane.barretto@oi.net.br> | M15: Bruno Macedo Soares <bmacedo@oi.net.br> | N15: Monica Sant Anna Paetzoldt <monica.paetzoldt@oi.net.br> | O15: -
B16: Bill-to-cash​ | C16: Postagem das faturas para os clientes ​ | D16: - Oi irá disponibilizar os documentos de faturamento de terminais móveis para as empresas de postagem, mantendo os sistemas, regras e processos atuais, até a migração total desses clientes, nos formatos e layout atuais (online e customizadas) para clientes varejo, empresarial e corporativos. | E16: - Oi irá disponibilizar os documentos de faturamento de terminais fibra para as empresas de postagem, mantendo os sistemas, regras e processos atuais, até a migração total desses clientes, nos formatos e layout atuais (online e customizadas) para clientes varejo e empresarial. - Os clientes digitais terão seu envio da forma que solicitaram, seja via email ou whatsapp | F16: Faturamento | G16: Monica | H16: Faturamento | J16: CONCLUÍDO | K16: Finanças e Relações com investidores | L16: Cristiane Barretto Sales <cristiane.barretto@oi.net.br> | M16: Bruno Macedo Soares <bmacedo@oi.net.br> | N16: Monica Sant Anna Paetzoldt <monica.paetzoldt@oi.net.br> | O16: -
B17: Bill-to-cash​ | C17: Execução dos processos de garantia da receita ​ | D17: - Execução mensal de certificações da receita de serviços de clientes pós-pagos dos segmentos varejo e empresarial nos processos de aprovisionamento, faturamento e cobrança para garantia de integridade do cliente entre essas etapas. - Execução mensal de certificações da receita de clientes pré-pago e controle nos processos de contabilização da receita, geração de nota fiscal e controle do saldo da plataforma (recarga - consumo x saldo). - Identificação, tratamento e report dos problemas encontrados mantendo os patamares de recuperação vigentes. - Geração dos reports executivos e operacionais mensais de casos e oportunidades de recuperação financeira. | E17: - Execução mensal de análise de variação da receita de serviços recorrentes dos segmentos varejo e empresarial nas principais alavancas (gross, churn, interrupções de faturamento, migrações, variações de clientes da base, etc) - Análise mensal das alavancas NTFGA (motivo de Terminais não Faturarem e Gerarem Assinatura) para serviços pós pagos. - Acompanhamento mensal da despesa de ITX e análise dos desvios (VOIP) | F17: RA/ Fraude | G17: Alessandro Varme | H17: RA/ Varme | J17: CONCLUÍDO | K17: Finanças e Relações com investidores | L17: Cristiane Barretto Sales <cristiane.barretto@oi.net.br> | M17: Bruno Macedo Soares <bmacedo@oi.net.br> | N17: Alessandro Luiz Varme Dias <alessandro.varme@oi.net.br> | O17: -
B18: Bill-to-cash​ | C18: Execução da cadeia de arrecadação​ | D18: - Execução dos processos de arrecadação bancária de acordo com processos, regras e sistemas atuais da Oi. - Troca de arquivos/informações com as instituições financeiras cadastradas. - Resolução de problemas encontrados durante o processamento | E18: - Execução dos processos de arrecadação bancária de acordo com processos, regras e sistemas atuais da Oi. - Troca de arquivos/informações com as instituições financeiras cadastradas. - Resolução de problemas encontrados durante o processamento | F18: Arrecadação e Cobrança | G18: Daniel Cattete | H18: Arrecadação/Cobrança/Daniel Cattete | J18: CONCLUÍDO | K18: Finanças e Relações com investidores | L18: Cristiane Barretto Sales <cristiane.barretto@oi.net.br> | M18: Bruno Macedo Soares <bmacedo@oi.net.br> | N18: Daniel Cattete Sanguedo <daniel.sanguedo@oi.net.br> | O18: -
B19: Bill-to-cash​ | C19: Execução da cadeia de débito automático ​ | D19: - Execução dos processos de débito automático de acordo com processos, regras e sistemas atuais da Oi. - Troca de arquivos/informações com as instituições cadastradas. - Resolução de problemas encontrados durante o processamento | E19: - Execução dos processos de débito automático de acordo com processos, regras e sistemas atuais da Oi. - Troca de arquivos/informações com as instituições cadastradas. - Resolução de problemas encontrados durante o processamento | F19: Arrecadação e Cobrança | G19: Daniel Cattete | H19: Arrecadação/Cobrança/Daniel Cattete | J19: CONCLUÍDO | K19: Finanças e Relações com investidores | L19: Cristiane Barretto Sales <cristiane.barretto@oi.net.br> | M19: Bruno Macedo Soares <bmacedo@oi.net.br> | N19: Daniel Cattete Sanguedo <daniel.sanguedo@oi.net.br> | O19: -
B20: Bill-to-cash​ | C20: Execução dos processos de fraude ​ | D20: - Execução dos processos de fraude técnica de acordo com as regras e modelos atuais da Oi. - Geração dos reports executivos e operacionais para estancar/reverter as perdas. - Resolução dos problemas encontrados durante o processamento. | E20: - Execução dos processos de fraude subscrição de acordo com as regras e modelos atuais da Oi no modelo preventivo, caso o processo de vendas fique a cargo da Oi. - Execução dos processos de fraude técnica de acordo com as regras e modelos atuais da Oi (spoofing, fishing, smishing, etc). - Tratamento de fraudes identificadas no modelo detectivo - pós instalação. (churn e contas a receber) - Tratamento de out layers de consumo (investigação, retirada e tratamento contábil) - Tratamento de reclamações de clientes com alegação de fraude, avaliando procedência / improcedência da contestação. | F20: RA/ Fraude | G20: Alessandro Varme | H20: Fraude | J20: CONCLUÍDO | K20: Finanças e Relações com investidores | L20: Cristiane Barretto Sales <cristiane.barretto@oi.net.br> | M20: Bruno Macedo Soares <bmacedo@oi.net.br> | N20: Alessandro Luiz Varme Dias <alessandro.varme@oi.net.br> | O20: -
B21: Bill-to-cash​ | C21: Execução da cadeia fiscal​ | D21: - Execução dos processos fiscais para as Compradoras de acordo com a legislação vigente respeitando as respectivas regras e modelos atuais da Oi. - Geração e envio das obrigações acessórias, apuração e pagamento da obrigação principal, de acordo com os sistemas e procedimentos atuais da Oi. - Consistência contábil, reports executivos e operacionais atualmente executados pela Oi. - Resolução dos problemas encontrados, referente ao processo de apuração durante a validação das obrigações acessórias e da obrigação principal. | E21: - Execução dos processos fiscais para as Compradoras de acordo com a legislação vigente respeitando as respectivas regras e modelos atuais da Oi. - Geração e envio das obrigações acessórias, apuração e pagamento da obrigação principal, de acordo com os sistemas e procedimentos atuais da Oi. - Consistência contábil, reports executivos e operacionais atualmente executados pela Oi. - Resolução dos problemas encontrados, referente ao processo de apuração durante a validação das obrigações acessórias e da obrigação principal. | F21: Tributos/Fiscal | G21: Erika Braga | H21: Tributos Indiretos/ Tribustos Diretos | I21: Seguindo as mesmas definições tributárias utilizadas para o TSA do MARS, tais como: utilização dos sistemas fiscais comply, ERP SAP; sem migração do saldo acumulado do CIAP; os mesmos relatórios fiscais para fins de informações gerenciais e analíticas, mesmas obrigações principais e acessórias entregues atualmente pela BTSA. | J21: CONCLUÍDO | K21: Finanças e Relações com investidores | L21: Cristiane Barretto Sales <cristiane.barretto@oi.net.br> | M21: Flavia Casali <flaviacasali@oi.net.br> | N21: Erika Braga <erika.braga@oi.net.br> | O21: -
B22: Bill-to-cash​ | C22: Execução da cadeia contábil​ | D22: - Execução das cadeias contábeis para as Compradoras de acordo com a legislação vigente respeitando as respectivas regras e modelos atuais da Oi- Carga dos arquivos no SAP da Oi. - Export dos dados para as Compradoras no formato acordado. - Envio dos arquivos dos convênios XXX, YYY e ZZZ para o fisco. - Confirmação de recebimento dos arquivos fiscais pelo Fisco- Resolução dos problemas encontrados durante o processamento. | E22: Execução das cadeias contábeis para as Compradoras de acordo com a legislação vigente respeitando as respectivas regras e modelos atuais da Oi- Carga dos arquivos no SAP da Oi, dos seguintes macro processos: 1- Receita, Descontos, ICMS e ISS, conforme ciclo dos Sistemas de Faturamento. 2- Arrecadação, Parcelamento de Fatura, Cancelamento e Contestação, conforme movimentos dos Sistema de Faturamento e Arrecadação. 3- Provisão p/ Créditos de Liquidação e Perdas, conforme movimentos dos Sistemas de Arrecadação. Export dos dados para as Compradoras no formato acordado. | F22: Contabilidade | G22: Marcelo Gomes | H22: Contabilidade | I22: Marcelo Gomes: o tópico foi alinhado com as áreas impacatdas, o ponto abaixo é apenas um detalhamento do que foi alinhado com as áreas impactadas. Deve ser avaliado pelos times de Tributos Diretos (Paulo Vidal) e Tributos Indiretos (Érika Braga): Envio dos arquivos dos convênios XXX, YYY e ZZZ para o fisco. Confirmação de recebimento dos arquivos fiscais pelo Fisco- Resolução dos problemas encontrados durante o processamento. Obs. O cálculo do PIS, COFINS, FUST e FUNTTEL é realizado pelo time de Tributos Diretos após a liberação/validação pela Contabilidade Operacional, conforme cronograma de fechamento. | J22: CONCLUÍDO | K22: Finanças e Relações com investidores | L22: Cristiane Barretto Sales <cristiane.barretto@oi.net.br> | M22: Andre Tavares Paradizi <andre.paradizi@oi.net.br> | N22: Francisco Paulo Macambira Haick <francisco.haick@oi.net.br> | O22: Marcelo Gomes <marcelo.gomes@oi.net.br>
B23: Bill-to-cash​ | C23: Execução da régua de cobrança - Classificação e reclassificação de status na régua ​ | D23: - Execução dos processos atuais da Oi associados à régua de cobrança para que os clientes evoluam dentro dos estágios existentes na régua. - Resolução dos problemas encontrados durante o processamento. | E23: - Execução dos processos atuais da Oi associados à régua de cobrança para que os clientes evoluam dentro dos estágios existentes na régua. - Resolução dos problemas encontrados durante o processamento. | F23: Arrecadação e Cobrança | G23: Daniel Cattete | H23: Arrecadação/Cobrança/Daniel Cattete | J23: CONCLUÍDO | K23: Finanças e Relações com investidores | L23: Cristiane Barretto Sales <cristiane.barretto@oi.net.br> | M23: Bruno Macedo Soares <bmacedo@oi.net.br> | N23: Daniel Cattete Sanguedo <daniel.sanguedo@oi.net.br> | O23: -
B24: Bill-to-cash​ | C24: Execução da régua de cobrança - Geração de notificação para clientes inadimplentes ​ | D24: - Execução dos processos atuais de comunicações/notificações da Oi conforme regras Regulatórias pertinentes à régua de cobrança. - Resolução dos problemas encontrados durante o processamento. | E24: - Execução dos processos atuais de comunicações/notificações da Oi conforme regras Regulatórias pertinentes à régua de cobrança. - Resolução dos problemas encontrados durante o processamento. | F24: Arrecadação e Cobrança | G24: Daniel Cattete | H24: Arrecadação/Cobrança/Daniel Cattete | J24: CONCLUÍDO | K24: Finanças e Relações com investidores | L24: Cristiane Barretto Sales <cristiane.barretto@oi.net.br> | M24: Bruno Macedo Soares <bmacedo@oi.net.br> | N24: Daniel Cattete Sanguedo <daniel.sanguedo@oi.net.br> | O24: -
B25: Bill-to-cash​ | C25: Mediação de bilhetes​ | D25: A Oi irá executar o processo de mediação de bilhetes de terminais móveis, mantendo os sistemas, regras e processos atuais, até a migração total desses clientes. - O tráfego dos CSPs das Compradoras continuarão a serem tratados como cobilling. - Análise de todo tipo de tráfego gerado (SMS, Dados, Voz, Cobilling) na entrada, saída e etapas intermediárias da Mediação. - Controle de críticas e descartes de bilhetes. - Resolução dos problemas encontrados durante o processamento da Mediação. - Recuperação e reprocessamento de bilhetes em casos necessários | E25: - A Oi irá executar o processo de mediação de bilhetes de terminais Voip da ClientCo, mantendo os sistemas, regras e processos atuais, até a migração total desses clientes. - Controle de críticas e descartes de bilhetes. - Resolução dos problemas encontrados durante o processamento da Mediação. - Recuperação e reprocessamento de bilhetes em casos necessários | F25: Tráfego | G25: Marcus Vinícius | H25: Tráfego/Marcus Vinícius | J25: CONCLUÍDO | K25: Finanças e Relações com investidores | L25: Cristiane Barretto Sales <cristiane.barretto@oi.net.br> | M25: Bruno Macedo Soares <bmacedo@oi.net.br> | N25: Altevo Carlos De Sa Volotao <altevo.volotao@oi.net.br> | O25: Marcus Vinicius Miguel De Oliveira <marcus.oliveira@oi.net.br>
B26: Bill-to-cash​ | C26: Recuperação de faturas​ | D26: - Oi deverá recuperar faturas antigas de terminais móveis, mediante solicitações judiciais, regulatórias ou obrigações tributárias, mantendo os sistemas, regras e processos atuais. | E26: - Oi deverá recuperar faturas antigas dos clientes da ClienteCo, mediante solicitações judiciais, regulatórias ou obrigações tributárias, mantendo os sistemas, regras e processos atuais. | F26: Jurídico Consumidor | G26: Anderson Nilson | H26: Jurídico Consumidor/ Regulatório/ Tributário | J26: CONCLUÍDO | K26: Jurídico | L26: Thalles Eduardo Silva Gracelacio Da Paixao <thalles.paixao@oi.net.br> | M26: Elen Marques Souto La Croix <elen.souto@oi.net.br> | N26: Adriana Velhote De Oliveira <adriana.velhote@oi.net.br> | O26: Anderson Nilson Rocha <anderson.rocha@oi.net.br>
B27: Bill-to-cash​ | C27: Recuperação de faturas​ | D27: - Oi deverá recuperar faturas antigas de terminais móveis, mediante solicitações judiciais, regulatórias ou obrigações tributárias, mantendo os sistemas, regras e processos atuais. | E27: Oi deverá recuperar faturas antigas , mediante solicitações judiciais, regulatórias ou obrigações tributárias, mantendo os sistemas, regras e processos atuais. | F27: Atendimento | G27: Giane Carla | H27: Atendimento/Giane Carla | I27: O tópico engloba o Atendimento e a Ouvidoria. | J27: EXCLUIR ESTE ITEM | K27: Oi Fibra | L27: Fabricio Bindi <fabricio.bindi@oi.net.br> | M27: Jomerson Da Silva Almeida <jomerson.almeida@oi.net.br> | N27: Giane Carla Varela <giane.varela@oi.net.br> | O27: -
B28: Bill-to-cash​ | C28: Parametrizações e Homologações​ | D28: - Oi deverá avaliar solicitações das Compradoras de parametrizações e/ ou projetos nos sistemas de billing quanto a viabilidade técnica, financeira, legal e regulatória. - As alterações implantadas deverão ser testadas e homologadas pela Oi e terão report para fins de acompanhamento do solicitante. | E28: - Oi deverá avaliar solicitações das Compradoras de parametrizações e/ ou projetos nos sistemas de billing quanto a viabilidade. - As alterações implantadas deverão ser testadas e homologadas pela Oi e terão report para fins de acompanhamento do solicitante. - Todas as alterações deverão ser únicas para todos os comprovadores, não podem haver divergencia de regra e pedido entre eles. financeira, legal e regulatória. | F28: Faturamento | G28: Iara | H28: Faturamento/Iara | J28: CONCLUÍDO | K28: Finanças e Relações com investidores | L28: Cristiane Barretto Sales <cristiane.barretto@oi.net.br> | M28: Bruno Macedo Soares <bmacedo@oi.net.br> | N28: Iara Kelli Da Cruz Braga <iara.braga@oi.net.br> | O28: -
B29: Bill-to-cash​ | C29: Criação dos dossiês de clientes inadimplentes para ajuizamento, cobrança extrajudicial e recuperação judicial ​ | D29: - Criação de dossiês com toda a documentação necessária e disponível para que o jurídico inicie os ajuizamentos. - Acompanhamento dos processos judiciais junto ao jurídico. | E29: - Criação de dossiês com toda a documentação necessária e disponível para que o jurídico inicie os ajuizamentos. | F29: Arrecadação e Cobrança | G29: Daniel Cattete | H29: Jur Consumidor/Fabrício | J29: CONCLUÍDO | K29: Finanças e Relações com investidores | L29: Cristiane Barretto Sales <cristiane.barretto@oi.net.br> | M29: Bruno Macedo Soares <bmacedo@oi.net.br> | N29: Daniel Cattete Sanguedo <daniel.sanguedo@oi.net.br> | O29: -
B30: Bill-to-cash​ | C30: Geração e distribuição de mailing e de relatórios de performance da operação ​ | D30: - Geração de mailings conforme regras atuais da Oi para a cobrança das assessorias. - Geração de relatórios de performance mensal atuais da Oi. | E30: - Geração de mailings conforme regras atuais da Oi para a cobrança das assessorias. - Geração de relatórios de performance mensal atuais da Oi. | F30: Arrecadação e Cobrança | G30: Daniel Cattete | H30: Faturamento// Contas a receber/ Cobrança | J30: CONCLUÍDO | K30: Finanças e Relações com investidores | L30: Cristiane Barretto Sales <cristiane.barretto@oi.net.br> | M30: Bruno Macedo Soares <bmacedo@oi.net.br> | N30: Daniel Cattete Sanguedo <daniel.sanguedo@oi.net.br> | O30: -
B31: Bill-to-cash​ | C31: Relatórios de CAR e PDD​ | D31: - Oi deverá gerar os relatórios gerenciais e analíticos de CAR e PDD com visão por segmento e por cliente de acordo com os prazos, formatos e capacidade tecnológica atuais. | E31: Oi deverá gerar os relatórios contábeis de CAR analítico por Unidade de Negócio, por Cliente e por Fatura, de acordo com os prazos. Oi deverá gerar os relatórios de PDD/PERDAS sintético por Unidade de Negócio, de acordo com os prazos. Oi deverá gerar o relatório de PDD Parcelamento analítico por Unidade de Negócio, por Cliente e por Fatura, de acordo com os prazos. | F31: Contabilidade | G31: Marcelo Gomes | H31: Contas a receber/Cobrança // Contabilidade | J31: CONCLUÍDO | K31: Finanças e Relações com investidores | L31: Cristiane Barretto Sales <cristiane.barretto@oi.net.br> | M31: Andre Tavares Paradizi <andre.paradizi@oi.net.br> | N31: Francisco Paulo Macambira Haick <francisco.haick@oi.net.br> | O31: Marcelo Gomes <marcelo.gomes@oi.net.br>
B32: Bill-to-cash​ | C32: Execução dos processos de Crédito​ | D32: - Oi deverá executar os processos de análise de crédito de acordo com as regras e modelos atuais, mantendo sistemas, políticas e níveis de serviços para as Compradoras tratando os problemas identificados e gerando os reports executivos e operacionais para acompanhamento do processo de aprovação de crédito. - A performance dessa operação será acompanhada em reports de aprovação e reports de performance de FPD nas visões e aberturas acompanhadas atualmente pela Oi, caso o processo de venda e aquisição ocorra nos CRM da Oi. - Este item não se refere a vendas, mas sim as movimentações na planta de clientes, p.ex., upgrades, downgrades, contratação de novas linhas móveis B2B, etc. | E32: Oi deverá executar os processos de análise de crédito de acordo com as regras e modelos atuais, mantendo sistemas, políticas e níveis de serviços para as Compradoras tratando os problemas identificados nos processos de aprovação de crédito. A performance dessa operação será acompanhada em reports de aprovação e reports de performance de FPD nas visões e aberturas acompanhadas atualmente pela Oi, caso o processo de venda e aquisição ocorra nos CRM da Oi. | F32: Crédito | G32: Bruno Simões | H32: Contas a receber/ Cobrança | I32: [Bruno Simões] - Descrição validada durante a reunião. | J32: CONCLUÍDO | K32: Finanças e Relações com investidores | L32: Cristiane Barretto Sales <cristiane.barretto@oi.net.br> | M32: Bruno Macedo Soares <bmacedo@oi.net.br> | N32: - | O32: Bruno Simoes <bruno.simoes@oi.net.br>
B33: Bill-to-cash​ | C33: Repasse da receita de Fibra das UPI´s ClientCo | D33: Novo tópico | E33: - Realização de repasse mensal da receita de Fibra, SVA, Oi Expert, Fibra X e Add on para as compradoras. - Resolução dos problemas encontrados durante apuração do repasse. | F33: Tráfego | G33: Marcus Vinícius | H33: Tráfego | J33: CONCLUÍDO | K33: Finanças e Relações com investidores | L33: Cristiane Barretto Sales <cristiane.barretto@oi.net.br> | M33: Bruno Macedo Soares <bmacedo@oi.net.br> | N33: Altevo Carlos De Sa Volotao <altevo.volotao@oi.net.br> | O33: Marcus Vinicius Miguel De Oliveira <marcus.oliveira@oi.net.br>
B34: Bill-to-cash​ | C34: Co-Billing Interno CSP´s de Outras Operadoras | D34: Novo tópico | E34: - A Oi S/A prestará o serviço de co-faturamento do CSP de Outras Operadoras originado por terminais Voip da ClientCo. | F34: Tráfego | G34: Marcus Vinícius | H34: Tráfego | J34: CONCLUÍDO | K34: Finanças e Relações com investidores | L34: Cristiane Barretto Sales <cristiane.barretto@oi.net.br> | M34: Bruno Macedo Soares <bmacedo@oi.net.br> | N34: Altevo Carlos De Sa Volotao <altevo.volotao@oi.net.br> | O34: Marcus Vinicius Miguel De Oliveira <marcus.oliveira@oi.net.br>
B35: Bill-to-cash​ | C35: Operação de Interconexão | D35: Novo tópico | E35: - A Oi irá executar o processo de apuração da Interconexão de bilhetes de terminais Voip da ClientCo, mantendo os sistemas, regras e processos atuais, até a migração total desses clientes. - Controle de críticas e descartes de bilhetes. - Resolução dos problemas encontrados durante o processamento da Interconexão. - Recuperação e reprocessamento de bilhetes em casos necessários | F35: Tráfego | G35: Marcus Vinícius | H35: Tráfego | J35: CONCLUÍDO | K35: Finanças e Relações com investidores | L35: Cristiane Barretto Sales <cristiane.barretto@oi.net.br> | M35: Bruno Macedo Soares <bmacedo@oi.net.br> | N35: Altevo Carlos De Sa Volotao <altevo.volotao@oi.net.br> | O35: Marcus Vinicius Miguel De Oliveira <marcus.oliveira@oi.net.br>
B36: Bill-to-cash​ | C36: Repasse de SVA/Terceiros/0500 | D36: Novo tópico | E36: - Realização da apuração periodica dos valores para repasse de parceiros de SVA/Terceiros/0500 mantendo os sistemas, regras e processos atuais, até a migração total desses clientes. - Resolução dos problemas encontrados durante apuração do repasse. | F36: Tráfego | G36: Marcus Vinícius | H36: Tráfego | J36: CONCLUÍDO | K36: Finanças e Relações com investidores | L36: Cristiane Barretto Sales <cristiane.barretto@oi.net.br> | M36: Bruno Macedo Soares <bmacedo@oi.net.br> | N36: Altevo Carlos De Sa Volotao <altevo.volotao@oi.net.br> | O36: Marcus Vinicius Miguel De Oliveira <marcus.oliveira@oi.net.br>
B37: Bill-to-cash​ | C37: Relacionamento Finaceiro com as Demais Operadoras | D37: Novo tópico | E37: - A Oi irá executar o processo de encontro de contas de Interconexão, mantendo os sistemas, regras e processos atuais, até a migração total desses clientes. - Resolução dos problemas encontrados durante apuração do repasse. | F37: Tráfego | G37: Marcus Vinícius | H37: Tráfego | J37: CONCLUÍDO | K37: Finanças e Relações com investidores | L37: Cristiane Barretto Sales <cristiane.barretto@oi.net.br> | M37: Bruno Macedo Soares <bmacedo@oi.net.br> | N37: Altevo Carlos De Sa Volotao <altevo.volotao@oi.net.br> | O37: Marcus Vinicius Miguel De Oliveira <marcus.oliveira@oi.net.br>
B38: Bill-to-cash​ | C38: Obrigação Fiscal (entrada NF/input SAP/retenções de impostos) - OPERAÇÃO BPO | D38: Novo tópico | E38: -A Oi deverá executar o processo de lançamentos das NF's de entrada no SAP, com as devidas retenções federais e municipais. - Execução dos controles internos conforme relação de controles existentes (SOX). - Devolutiva das criticas para as NF não lançadas pelo Posto Fiscal | F38: Tributos/Fiscal | G38: Hozana Guimarães | H38: Tributos/Fiscal | J38: CONCLUÍDO | K38: Finanças e Relações com investidores | L38: Cristiane Barretto Sales <cristiane.barretto@oi.net.br> | M38: Flavia Casali <flaviacasali@oi.net.br> | N38: Hozana Guimaraes De Sa Braga <hozana.braga@oi.net.br> | O38: -
B39: Bill-to-cash​ | C39: Criação de Requisições de compras e pedidos(célula adm) - OPERAÇÃO BPO | D39: Novo tópico | E39: - A Oi deverá criar os novos pedidos de compras conforme demandas de serviços e equipamentos que estiverem vinculados aos contratos e verba disponiveis para as ClientCO's | F39: Tributos/Fiscal | G39: Hozana Guimarães | H39: Diversas áreas | J39: CONCLUÍDO | K39: Finanças e Relações com investidores | L39: Cristiane Barretto Sales <cristiane.barretto@oi.net.br> | M39: Flavia Casali <flaviacasali@oi.net.br> | N39: Hozana Guimaraes De Sa Braga <hozana.braga@oi.net.br> | O39: -
B40: Bill-to-cash​ | C40: Criação e Manutenção dos cadastros de Fornecedores, Clientes, códigos de materiais e serviços | D40: Novo tópico | E40: - A Oi deverá executar o processo de cadastro no SAP para as demandas referentes a criação de novos fornecedores, clientes, codigos de materiais e serviços, manutenção dos cadastros ( atualização de dados bancários, ampliações de centros, paramentros de códigos para corretas contabilizações, ajustes de aliquotas, domicilio fiscal etc, conforme necessidade que surgirem no periodo após drop. -Extração de relatório com as demandas que forem solicitadas no periodo. | F40: Tributos/Fiscal | G40: Hozana Guimarães | H40: Diversas áreas | J40: CONCLUÍDO | K40: Finanças e Relações com investidores | L40: Cristiane Barretto Sales <cristiane.barretto@oi.net.br> | M40: Flavia Casali <flaviacasali@oi.net.br> | N40: Hozana Guimaraes De Sa Braga <hozana.braga@oi.net.br> | O40: -
B41: Bill-to-cash​ | C41: Portal de Notas (Sistema de acesso de fornecedores, gestores de aceite e usuários do Posto Fiscal) | D41: Novo tópico | E41: - A Oi deverá garantir o processo sistemico de cadastro, armazenamento das NF's de entrada no BRNOTAS, integração com sistemas SAP para escrituração fiscal no SAP. - Extração de relatórios das NF cadastrdas, com status de tratamento. - Consulta das NF emitidas contra as ClientC0's | F41: Tributos/Fiscal | G41: Hozana Guimarães | H41: Tributos/Fiscal | J41: CONCLUÍDO | K41: Finanças e Relações com investidores | L41: Cristiane Barretto Sales <cristiane.barretto@oi.net.br> | M41: Flavia Casali <flaviacasali@oi.net.br> | N41: Hozana Guimaraes De Sa Braga <hozana.braga@oi.net.br> | O41: -
...

Sheet Anexo A - TODOS OS SERVIÇOS
B2: Nome da VP | C2: Resumo dos serviços descritos no TSA. | D2: Topicos | E2: Texto Anexo A (ClientCo) | F2: Área responsável pelo Report | G2: Pessoa responsável pelo Report | H2: Áreas impactadas | I2: Anotações | J2: Status Anexo A | K2: N1 | L2: N2 | M2: N3 | N2: N4/ Consultor
B3: Auditoria e GRC | C3: Bill-to-cash​ | D3: Riscos e Controles | E3: - Revisão, atualização e teste de controles do Ambiente de Controles Internos da Companhia que permeiam todos os processos; - Gestão das Alçadas da Companhia que permeiam as principais atividades de aprovação; - Avaliação de Riscos conforme demanda das áreas; - Gestão dos Riscos Corporativos; - Gestão dos documentos da Companhia; - GCN que podem envolver incidentes/crises que impactam o serviço da Fibra. | F3: Controles Internos | G3: Kamila de Vasconcelos | J3: CONCLUÍDO | K3: Duilio De Novaes Alves <duilio.alves@oi.net.br> | L3: Duilio De Novaes Alves <duilio.alves@oi.net.br> | M3: Kamila De Vasconcelos Vieira <kamila.vieira@oi.net.br> | N3: -
B4: Auditoria e GRC | C4: Bill-to-cash​ | D4: Conformidade e Sustentabilidade | E4: - Gestão do canal e atendimento às solicitações de direitos previstos na LGPD por parte de titulares de dados pessoais; - Avaliação e adequação de contratos e editais, sob o aspecto de privacidade e proteção de dados pessoais, com fornecedores, parceiros e clientes (empresariais); - Manutenção do registro de operações de tratamento de dados pessoais, na forma do art. 37 da LGPD; - Identificação e registro de transferências internacionais de dados pessoais na forma do art. 33 da LGPD; - Identificação, avaliação e tratamento de riscos de privacidade em processos e projetos da Companhia; - Gestão, tratamento e comunicação - sob demanda - de eventuais incidentes de segurança que envolvam dados pessoais; - Resposta à ofícios e requerimentos de autoridades públicas, relacionados à privacidade; - Gestão do canal de denúncias e apuração de relatos; - Avaliação e adequação da cláusula de Compliance em contratos e editais; - Realização de análise de integridade de terceiros e colaboradores; - Realização de testes detectivos de conflitos de interesse; pagamentos à agentes públicos; doações; Brindes e Presentes e etc; - Resposta à Due Diligence de Terceiros, Parceiros; Investidores e Clientes; - Realização de processos de Partes Relacionadas; Acompanhamento de relacionamento com países em lista de sanções internacionais. | F4: Controles Internos | G4: Kamila de Vasconcelos | J4: CONCLUÍDO | K4: Duilio De Novaes Alves <duilio.alves@oi.net.br> | L4: Duilio De Novaes Alves <duilio.alves@oi.net.br> | M4: Kamila De Vasconcelos Vieira <kamila.vieira@oi.net.br> | N4: -
B5: Auditoria e GRC | C5: Bill-to-cash​ | D5: Auditoria Interna | E5: - Apuração de casos fraude; - Auditoria de sistemas e processos que permeiam toda a Cia de acordo com o plano aprovado; - Acompanhamento e “reteste” de ações corretivas; - Monitoramento de fraude em processos críticos. | F5: Controles Internos | G5: Kamila de Vasconcelos | J5: CONCLUÍDO | K5: Duilio De Novaes Alves <duilio.alves@oi.net.br> | L5: Duilio De Novaes Alves <duilio.alves@oi.net.br> | M5: Kamila De Vasconcelos Vieira <kamila.vieira@oi.net.br> | N5: -
B6: Finanças e Relações com investidores | C6: Bill-to-cash​ | D6: Execução de ciclos de Billings​ | E6: - A Oi deverá executar o processo de faturamento de terminais fibra, mantendo os sistemas, regras e processos atuais, até a migração total desses clientes. - Execução de todos os ciclos de billings (majoritários e minoritários) em todos os sistemas de faturamento existentes no parque de TI. - Resolução dos problemas encontrados durante o processamento. | F6: Faturamento | G6: Monica | H6: Faturamento | J6: CONCLUÍDO | K6: Cristiane Barretto Sales <cristiane.barretto@oi.net.br> | L6: Bruno Macedo Soares <bmacedo@oi.net.br> | M6: Monica Sant Anna Paetzoldt <monica.paetzoldt@oi.net.br> | N6: -
B7: Finanças e Relações com investidores | C7: Bill-to-cash​ | D7: Tarifação de chamadas, dados e eventos ​ | E7: - Realização do processo de Tarifação de Voz, SVA e 0500 mantendo os sistemas, regras, processos e produtos e ofertas atuais, até a migração total desses clientes. - Resolução dos problemas encontrados durante o processamento. | F7: Tráfego | G7: Marcus Vinícius | H7: Faturamento// Tarifação e Repasse | J7: CONCLUÍDO | K7: Cristiane Barretto Sales <cristiane.barretto@oi.net.br> | L7: Bruno Macedo Soares <bmacedo@oi.net.br> | M7: Altevo Carlos De Sa Volotao <altevo.volotao@oi.net.br> | N7: Marcus Vinicius Miguel De Oliveira <marcus.oliveira@oi.net.br>
B8: Finanças e Relações com investidores | C8: Bill-to-cash​ | D8: Emissão de termos de quitação​ | E8: - Emissão do termo de quitação referentes aos pagamentos das últimas faturas dos clientes fibra. - Resolução dos problemas encontrados durante o processamento. - Todas as pendências de emissão dos termos de quitação anteriores a data do fechamento do contrato deverão ser regularizadas. | F8: Faturamento | G8: Monica | H8: Fatutamento/ Atendimento | J8: CONCLUÍDO | K8: Cristiane Barretto Sales <cristiane.barretto@oi.net.br> | L8: Bruno Macedo Soares <bmacedo@oi.net.br> | M8: Monica Sant Anna Paetzoldt <monica.paetzoldt@oi.net.br> | N8: -
B9: Finanças e Relações com investidores | C9: Bill-to-cash​ | D9: Validação do billings gerados - consistência, qualidade e confiabilidade ​ | E9: - A Oi irá executar o processo de validação prévia de faturas de terminais fibra, mantendo os sistemas, regras e processos atuais, até a migração total desses clientes. - Corrigir e reportar o tratamento adotado em caso de desvios identificados mantendo os sistemas, regras, processos e performance atuais, até a migração total desses clientes. -Executar as validações de consistência sobre o ciclo de billing executado. | F9: Faturamento | G9: Monica | H9: Faturamento | J9: CONCLUÍDO | K9: Cristiane Barretto Sales <cristiane.barretto@oi.net.br> | L9: Bruno Macedo Soares <bmacedo@oi.net.br> | M9: Monica Sant Anna Paetzoldt <monica.paetzoldt@oi.net.br> | N9: -
B10: Finanças e Relações com investidores | C10: Bill-to-cash​ | D10: Disponibilização de faturas online e customizadas ​ | E10: - Oi irá disponibilizar as faturas de terminais fibra, mantendo os sistemas, regras e processos atuais, até a migração total desses clientes, nos formatos e layout atuais (online e customizadas) para clientes varejo e empresarial. - Carga dos spools faturados nas ferramentas que disponibilizam online os documentos de faturamento. - Resolução dos problemas encontrados durante o processamento. - Eventuais necessidades de alterações deverão ser discutidas em relação à custo e prazo. | F10: Faturamento | G10: Monica | H10: Fatutamento/ Atendimento | J10: CONCLUÍDO | K10: Cristiane Barretto Sales <cristiane.barretto@oi.net.br> | L10: Bruno Macedo Soares <bmacedo@oi.net.br> | M10: Monica Sant Anna Paetzoldt <monica.paetzoldt@oi.net.br> | N10: -
B11: Finanças e Relações com investidores | C11: Bill-to-cash​ | D11: Envio dos spools para as print centers ​ | E11: - Oi irá disponibilizar os spools de faturas de terminais fibra para as print centers atuais da Oi (e remunerar os print centers), mantendo os sistemas, regras e processos atuais, até a migração total desses clientes, nos formatos e layout atuais (online e customizadas) para clientes varejo e empresarial. - Conferência do faturamento gerado e consistências cadastrais. - Disponibilização dos documentos para as empresas de postagem. | F11: Faturamento | G11: Monica | H11: Faturamento | J11: CONCLUÍDO | K11: Cristiane Barretto Sales <cristiane.barretto@oi.net.br> | L11: Bruno Macedo Soares <bmacedo@oi.net.br> | M11: Monica Sant Anna Paetzoldt <monica.paetzoldt@oi.net.br> | N11: -
B12: Finanças e Relações com investidores | C12: Bill-to-cash​ | D12: Postagem das faturas para os clientes ​ | E12: - Oi irá disponibilizar os documentos de faturamento de terminais fibra para as empresas de postagem, mantendo os sistemas, regras e processos atuais, até a migração total desses clientes, nos formatos e layout atuais (online e customizadas) para clientes varejo e empresarial. - Os clientes digitais terão seu envio da forma que solicitaram, seja via email ou whatsapp | F12: Faturamento | G12: Monica | H12: Faturamento | J12: CONCLUÍDO | K12: Cristiane Barretto Sales <cristiane.barretto@oi.net.br> | L12: Bruno Macedo Soares <bmacedo@oi.net.br> | M12: Monica Sant Anna Paetzoldt <monica.paetzoldt@oi.net.br> | N12: -
B13: Finanças e Relações com investidores | C13: Bill-to-cash​ | D13: Execução dos processos de garantia da receita ​ | E13: - Execução mensal de análise de variação da receita de serviços recorrentes dos segmentos varejo e empresarial nas principais alavancas (gross, churn, interrupções de faturamento, migrações, variações de clientes da base, etc) - Análise mensal das alavancas NTFGA (motivo de Terminais não Faturarem e Gerarem Assinatura) para serviços pós pagos. - Acompanhamento mensal da despesa de ITX e análise dos desvios (VOIP) | F13: RA/ Fraude | G13: Alessandro Varme | H13: RA/ Varme | J13: CONCLUÍDO | K13: Cristiane Barretto Sales <cristiane.barretto@oi.net.br> | L13: Bruno Macedo Soares <bmacedo@oi.net.br> | M13: Alessandro Luiz Varme Dias <alessandro.varme@oi.net.br> | N13: -
B14: Finanças e Relações com investidores | C14: Bill-to-cash​ | D14: Execução da cadeia de arrecadação​ | E14: - Execução dos processos de arrecadação bancária de acordo com processos, regras e sistemas atuais da Oi. - Troca de arquivos/informações com as instituições financeiras cadastradas. - Resolução de problemas encontrados durante o processamento | F14: Arrecadação e Cobrança | G14: Daniel Cattete | H14: Arrecadação/Cobrança/Daniel Cattete | J14: CONCLUÍDO | K14: Cristiane Barretto Sales <cristiane.barretto@oi.net.br> | L14: Bruno Macedo Soares <bmacedo@oi.net.br> | M14: Daniel Cattete Sanguedo <daniel.sanguedo@oi.net.br> | N14: -
B15: Finanças e Relações com investidores | C15: Bill-to-cash​ | D15: Execução da cadeia de débito automático ​ | E15: - Execução dos processos de débito automático de acordo com processos, regras e sistemas atuais da Oi. - Troca de arquivos/informações com as instituições cadastradas. - Resolução de problemas encontrados durante o processamento | F15: Arrecadação e Cobrança | G15: Daniel Cattete | H15: Arrecadação/Cobrança/Daniel Cattete | J15: CONCLUÍDO | K15: Cristiane Barretto Sales <cristiane.barretto@oi.net.br> | L15: Bruno Macedo Soares <bmacedo@oi.net.br> | M15: Daniel Cattete Sanguedo <daniel.sanguedo@oi.net.br> | N15: -
B16: Finanças e Relações com investidores | C16: Bill-to-cash​ | D16: Execução dos processos de fraude ​ | E16: - Execução dos processos de fraude subscrição de acordo com as regras e modelos atuais da Oi no modelo preventivo, caso o processo de vendas fique a cargo da Oi. - Execução dos processos de fraude técnica de acordo com as regras e modelos atuais da Oi (spoofing, fishing, smishing, etc). - Tratamento de fraudes identificadas no modelo detectivo - pós instalação. (churn e contas a receber) - Tratamento de out layers de consumo (investigação, retirada e tratamento contábil) - Tratamento de reclamações de clientes com alegação de fraude, avaliando procedência / improcedência da contestação. | F16: RA/ Fraude | G16: Alessandro Varme | H16: Fraude | J16: CONCLUÍDO | K16: Cristiane Barretto Sales <cristiane.barretto@oi.net.br> | L16: Bruno Macedo Soares <bmacedo@oi.net.br> | M16: Alessandro Luiz Varme Dias <alessandro.varme@oi.net.br> | N16: -
B17: Finanças e Relações com investidores | C17: Bill-to-cash​ | D17: Execução da cadeia fiscal​ | E17: - Execução dos processos fiscais para as Compradoras de acordo com a legislação vigente respeitando as respectivas regras e modelos atuais da Oi. - Geração e envio das obrigações acessórias, apuração e pagamento da obrigação principal, de acordo com os sistemas e procedimentos atuais da Oi. - Consistência contábil, reports executivos e operacionais atualmente executados pela Oi. - Resolução dos problemas encontrados, referente ao processo de apuração durante a validação das obrigações acessórias e da obrigação principal. | F17: Tributos/Fiscal | G17: Erika Braga | H17: Tributos Indiretos/ Tribustos Diretos | I17: Seguindo as mesmas definições tributárias utilizadas para o TSA do MARS, tais como: utilização dos sistemas fiscais comply, ERP SAP; sem migração do saldo acumulado do CIAP; os mesmos relatórios fiscais para fins de informações gerenciais e analíticas, mesmas obrigações principais e acessórias entregues atualmente pela BTSA. | J17: CONCLUÍDO | K17: Cristiane Barretto Sales <cristiane.barretto@oi.net.br> | L17: Flavia Casali <flaviacasali@oi.net.br> | M17: Erika Braga <erika.braga@oi.net.br> | N17: -
B18: Finanças e Relações com investidores | C18: Bill-to-cash​ | D18: Execução da cadeia contábil​ | E18: Execução das cadeias contábeis para as Compradoras de acordo com a legislação vigente respeitando as respectivas regras e modelos atuais da Oi- Carga dos arquivos no SAP da Oi, dos seguintes macro processos: 1- Receita, Descontos, ICMS e ISS, conforme ciclo dos Sistemas de Faturamento. 2- Arrecadação, Parcelamento de Fatura, Cancelamento e Contestação, conforme movimentos dos Sistema de Faturamento e Arrecadação. 3- Provisão p/ Créditos de Liquidação e Perdas, conforme movimentos dos Sistemas de Arrecadação. Export dos dados para as Compradoras no formato acordado. | F18: Contabilidade | G18: Marcelo Gomes | H18: Contabilidade | I18: Marcelo Gomes: o tópico foi alinhado com as áreas impacatdas, o ponto abaixo é apenas um detalhamento do que foi alinhado com as áreas impactadas. Deve ser avaliado pelos times de Tributos Diretos (Paulo Vidal) e Tributos Indiretos (Érika Braga): Envio dos arquivos dos convênios XXX, YYY e ZZZ para o fisco. Confirmação de recebimento dos arquivos fiscais pelo Fisco- Resolução dos problemas encontrados durante o processamento. Obs. O cálculo do PIS, COFINS, FUST e FUNTTEL é realizado pelo time de Tributos Diretos após a liberação/validação pela Contabilidade Operacional, conforme cronograma de fechamento. | J18: CONCLUÍDO | K18: Cristiane Barretto Sales <cristiane.barretto@oi.net.br> | L18: Andre Tavares Paradizi <andre.paradizi@oi.net.br> | M18: Francisco Paulo Macambira Haick <francisco.haick@oi.net.br> | N18: Marcelo Gomes <marcelo.gomes@oi.net.br>
B19: Finanças e Relações com investidores | C19: Bill-to-cash​ | D19: Execução da régua de cobrança - Classificação e reclassificação de status na régua ​ | E19: - Execução dos processos atuais da Oi associados à régua de cobrança para que os clientes evoluam dentro dos estágios existentes na régua. - Resolução dos problemas encontrados durante o processamento. | F19: Arrecadação e Cobrança | G19: Daniel Cattete | H19: Arrecadação/Cobrança/Daniel Cattete | J19: CONCLUÍDO | K19: Cristiane Barretto Sales <cristiane.barretto@oi.net.br> | L19: Bruno Macedo Soares <bmacedo@oi.net.br> | M19: Daniel Cattete Sanguedo <daniel.sanguedo@oi.net.br> | N19: -
B20: Finanças e Relações com investidores | C20: Bill-to-cash​ | D20: Execução da régua de cobrança - Geração de notificação para clientes inadimplentes ​ | E20: - Execução dos processos atuais de comunicações/notificações da Oi conforme regras Regulatórias pertinentes à régua de cobrança. - Resolução dos problemas encontrados durante o processamento. | F20: Arrecadação e Cobrança | G20: Daniel Cattete | H20: Arrecadação/Cobrança/Daniel Cattete | J20: CONCLUÍDO | K20: Cristiane Barretto Sales <cristiane.barretto@oi.net.br> | L20: Bruno Macedo Soares <bmacedo@oi.net.br> | M20: Daniel Cattete Sanguedo <daniel.sanguedo@oi.net.br> | N20: -
B21: Finanças e Relações com investidores | C21: Bill-to-cash​ | D21: Mediação de bilhetes​ | E21: - A Oi irá executar o processo de mediação de bilhetes de terminais Voip da ClientCo, mantendo os sistemas, regras e processos atuais, até a migração total desses clientes. - Controle de críticas e descartes de bilhetes. - Resolução dos problemas encontrados durante o processamento da Mediação. - Recuperação e reprocessamento de bilhetes em casos necessários | F21: Tráfego | G21: Marcus Vinícius | H21: Tráfego/Marcus Vinícius | J21: CONCLUÍDO | K21: Cristiane Barretto Sales <cristiane.barretto@oi.net.br> | L21: Bruno Macedo Soares <bmacedo@oi.net.br> | M21: Altevo Carlos De Sa Volotao <altevo.volotao@oi.net.br> | N21: Marcus Vinicius Miguel De Oliveira <marcus.oliveira@oi.net.br>
B22: Finanças e Relações com investidores | C22: Bill-to-cash​ | D22: Parametrizações e Homologações​ | E22: - Oi deverá avaliar solicitações das Compradoras de parametrizações e/ ou projetos nos sistemas de billing quanto a viabilidade. - As alterações implantadas deverão ser testadas e homologadas pela Oi e terão report para fins de acompanhamento do solicitante. - Todas as alterações deverão ser únicas para todos os comprovadores, não podem haver divergencia de regra e pedido entre eles. financeira, legal e regulatória. | F22: Faturamento | G22: Iara | H22: Faturamento/Iara | J22: CONCLUÍDO | K22: Cristiane Barretto Sales <cristiane.barretto@oi.net.br> | L22: Bruno Macedo Soares <bmacedo@oi.net.br> | M22: Iara Kelli Da Cruz Braga <iara.braga@oi.net.br> | N22: -
